<?xml version="1.0"?>
<robot name="orthrus"
  xmlns:xacro="http://ros.org/wiki/xacro">

  <xacro:property name="meshes_folder" value="file:///$(find orthrus_gazebo)/models/orthrus/meshes" />

  <material name="blue">
    <color rgba="0 0 0.8 1"/>
  </material>

  <material name="black">
    <color rgba="0 0 0 1"/>
  </material>

  <material name="white">
    <color rgba="1 1 1 1"/>
  </material>

  <link name="body">
    <visual>
      <origin xyz="-0.10 0.1385 -0.05" rpy="${pi/2} 0 0" />
      <geometry>
        <mesh filename="${meshes_folder}/body.STL"/>
      </geometry>
      <material name="blue"/>
    </visual>
    <collision>
      <origin xyz="-0.10 0.1385 -0.05" rpy="${pi/2} 0 0" />
      <geometry>
        <mesh filename="${meshes_folder}/body.STL"/>
      </geometry>
    </collision>
    <inertial>
      <mass value="7"/>
      <inertia ixx="4.9950395" ixy="0" ixz="0" iyy="2.4616377" iyz="0" izz="6.4183150" />
    </inertial>
  </link>

  <link name="imu_link">
  </link>

  <joint name="imu_joint" type="fixed">
    <parent link="body"/>
    <child link="imu_link"/>
  </joint>

  <xacro:macro name="hip" params="prefix">
    <link name="hip_${prefix}">
      <visual>
        <origin xyz="-0.02 -0.05 -0.05" rpy="0 0 0" />
        <geometry>
          <mesh filename="${meshes_folder}/hip.STL"/>
        </geometry>
        <material name="black"/>
      </visual>
      <collision>
        <origin xyz="-0.02 -0.05 -0.05" rpy="0 0 0" />
        <geometry>
          <mesh filename="${meshes_folder}/hip.STL"/>
        </geometry>
      </collision>
      <inertial>
        <mass value="0.7"/>
        <inertia ixx="0.0904981" ixy="0" ixz="-0.0000480" iyy=" 0.0917319" iyz="0" izz="0.0857923" />
      </inertial>
    </link>

    <joint name="hip_${prefix}_joint" type="revolute">
      <axis xyz="0 0 1"/>
      <parent link="body"/>
      <child link="hip_${prefix}"/>
      <dynamics damping="0.4" friction="0.3"/>
      <limit effort="35.0" lower="-${pi/2}" upper="${pi/2}" velocity="${pi}"/>
      <xacro:if value="${prefix == 'LF'}">
        <origin xyz="-0.05 0.20 0" rpy="${pi/2} ${pi} 0" />
      </xacro:if>
      <xacro:if value="${prefix == 'LB'}">
        <origin xyz="-0.05 -0.20 0" rpy="-${pi/2} ${pi} 0" />
      </xacro:if>
      <xacro:if value="${prefix == 'RB'}">
        <origin xyz="0.05 -0.20 0" rpy="${pi/2} ${pi} ${pi}" />
      </xacro:if>
      <xacro:if value="${prefix == 'RF'}">
        <origin xyz="0.05 0.20 0" rpy="-${pi/2} ${pi} ${pi}" />
      </xacro:if>

    </joint>
  </xacro:macro>

  <xacro:hip prefix="RF"/>
  <xacro:hip prefix="LF"/>
  <xacro:hip prefix="RB"/>
  <xacro:hip prefix="LB"/>

  <xacro:macro name="leg1" params="prefix">
    <link name="leg1_${prefix}">
      <visual>
        <origin xyz="0 -0.2 -0.05" rpy="0 0 0" />
        <geometry>
          <mesh filename="${meshes_folder}/leg1.STL"/>
        </geometry>
        <material name="black"/>
      </visual>
      <collision>
        <origin xyz="0 -0.2 -0.05" rpy="0 0 0" />
        <geometry>
          <mesh filename="${meshes_folder}/leg1.STL"/>
        </geometry>
      </collision>
      <inertial>
        <mass value="1"/>
        <inertia ixx="0.4329464" ixy="-0.0830239" ixz=" -0.0000001" iyy="0.1503071" iyz="0.0000001" izz="0.4817994" />
      </inertial>
    </link>

    <joint name="leg1_${prefix}_joint" type="revolute">
      <axis xyz="1 0 0"/>
      <parent link="hip_${prefix}"/>
      <child link="leg1_${prefix}"/>
      <dynamics damping="0.4" friction="0.3"/>
      <limit effort="35.0" lower="-${pi*2/3}" upper="${pi*2/3}" velocity="${pi}"/>
      <xacro:if value="${prefix == 'LF'}">
        <origin xyz="0.05 0 0" rpy="-${pi/2} 0 0" />
      </xacro:if>
      <xacro:if value="${prefix == 'LB'}">
        <origin xyz="0.05 0 0" rpy="${pi/2} 0 0" />
      </xacro:if>
      <xacro:if value="${prefix == 'RB'}">
        <origin xyz="0.05 0 0" rpy="${pi/2} 0 0" />
      </xacro:if>
      <xacro:if value="${prefix == 'RF'}">
        <origin xyz="0.05 0 0" rpy="-${pi/2} 0 0" />
      </xacro:if>
    </joint>
  </xacro:macro>

  <xacro:leg1 prefix="RF"/>
  <xacro:leg1 prefix="LF"/>
  <xacro:leg1 prefix="RB"/>
  <xacro:leg1 prefix="LB"/>

  <xacro:macro name="leg2" params="prefix">
    <link name="leg2_${prefix}">
      <visual>
        <origin xyz="-0.025 -0.025 -0.225" rpy="0 0 0" />
        <geometry>
          <mesh filename="${meshes_folder}/leg2.STL"/>
        </geometry>
        <material name="black"/>
      </visual>
      <collision>
        <origin xyz="-0.025 -0.025 -0.225" rpy="0 0 0" />
        <geometry>
          <mesh filename="${meshes_folder}/leg2.STL"/>
        </geometry>
      </collision>
      <inertial>
        <mass value="0.2"/>
        <inertia ixx="0.4201680" ixy="0" ixz="0" iyy="0.4196489" iyz="0" izz="0.0031965" />
      </inertial>
    </link>

    <joint name="leg2_${prefix}_joint" type="revolute">
      <axis xyz="1 0 0"/>
      <parent link="leg1_${prefix}"/>
      <child link="leg2_${prefix}"/>
      <dynamics damping="0.4" friction="0.3"/>

      <xacro:if value="${prefix == 'LF'}">
        <origin xyz="0.035 -0.18 0" rpy="${pi*2/3} 0 0" />
        <limit effort="35.0" lower="-${pi*1/12}" upper="${pi*2/3}" velocity="${pi}"/>
      </xacro:if>
      <xacro:if value="${prefix == 'RF'}">
        <origin xyz="0.035 -0.18 0" rpy="${pi*1/3} 0 0" />
        <limit effort="35.0" lower="-${pi*2/3}" upper="${pi*1/12}" velocity="${pi}"/>
      </xacro:if>
      <xacro:if value="${prefix == 'RB'}">
        <origin xyz="0.035 -0.18 0" rpy="${pi*1/3} 0 0" />
        <limit effort="35.0" lower="-${pi*2/3}" upper="${pi*1/12}" velocity="${pi}"/>
      </xacro:if>
      <xacro:if value="${prefix == 'LB'}">
        <origin xyz="0.035 -0.18 0" rpy="${pi*2/3} 0 0" />
        <limit effort="35.0" lower="-${pi*1/12}" upper="${pi*2/3}" velocity="${pi}"/>
      </xacro:if>

    </joint>
  </xacro:macro>

  <xacro:leg2 prefix="LF"/>
  <xacro:leg2 prefix="RF"/>
  <xacro:leg2 prefix="LB"/>
  <xacro:leg2 prefix="RB"/>

  <xacro:macro name="ros2_hip_joint" params="prefix">
    <joint name="hip_${prefix}_joint">
      <command_interface name="effort">
        <param name="min">-35</param>
        <param name="max">35</param>
      </command_interface>
      <state_interface name="position"/>
      <state_interface name="velocity"/>
      <state_interface name="effort"/>
    </joint>
  </xacro:macro>

  <xacro:macro name="ros2_leg1_joint" params="prefix">
    <joint name="leg1_${prefix}_joint">
      <command_interface name="effort">
        <param name="min">-35</param>
        <param name="max">35</param>
      </command_interface>
      <state_interface name="position"/>
      <state_interface name="velocity"/>
      <state_interface name="effort"/>
    </joint>
  </xacro:macro>

  <xacro:macro name="ros2_leg2_joint" params="prefix">
    <joint name="leg2_${prefix}_joint">
      <command_interface name="effort">
        <param name="min">-35</param>
        <param name="max">35</param>
      </command_interface>
      <state_interface name="position"/>
      <state_interface name="velocity"/>
      <state_interface name="effort"/>
    </joint>
  </xacro:macro>

  <ros2_control name="GazeboSystem" type="system">
    <hardware>
      <plugin>gazebo_ros2_control/GazeboSystem</plugin>
    </hardware>

    <xacro:ros2_hip_joint prefix="RF"/>
    <xacro:ros2_leg1_joint prefix="RF"/>
    <xacro:ros2_leg2_joint prefix="RF"/>

    <xacro:ros2_hip_joint prefix="LF"/>
    <xacro:ros2_leg1_joint prefix="LF"/>
    <xacro:ros2_leg2_joint prefix="LF"/>

    <xacro:ros2_hip_joint prefix="RB"/>
    <xacro:ros2_leg1_joint prefix="RB"/>
    <xacro:ros2_leg2_joint prefix="RB"/>

    <xacro:ros2_hip_joint prefix="LB"/>
    <xacro:ros2_leg1_joint prefix="LB"/>
    <xacro:ros2_leg2_joint prefix="LB"/>
    
    <sensor name="imu_sensor">
      <state_interface name="orientation.x"/>
      <state_interface name="orientation.y"/>
      <state_interface name="orientation.z"/>
      <state_interface name="orientation.w"/>
      <state_interface name="angular_velocity.x"/>
      <state_interface name="angular_velocity.y"/>
      <state_interface name="angular_velocity.z"/>
      <state_interface name="linear_acceleration.x"/>
      <state_interface name="linear_acceleration.y"/>
      <state_interface name="linear_acceleration.z"/>
    </sensor>

  </ros2_control>

  <gazebo reference="imu_link">
    <sensor name="imu_sensor" type="imu">
      <always_on>true</always_on>
      <update_rate>1000</update_rate>
    </sensor>
  </gazebo>

  <gazebo>
    <plugin filename="libgazebo_ros2_control.so" name="gazebo_ros2_control">
      <parameters>/home/evence/code_file/ros2_ws/orthrus/src/orthrus_ros2_pack/orthrus_sim/orthrus_gazebo/config/orthrus.yaml</parameters>
    </plugin>
  </gazebo>
</robot>

