<?xml version="1.0" ?>
<!-- =================================================================================== -->
<!-- |    This document was autogenerated by xacro from r2d.urdf.xacro                 | -->
<!-- |    EDITING THIS FILE BY HAND IS NOT RECOMMENDED                                 | -->
<!-- =================================================================================== -->
<robot name="gazebo1">
  <material name="blue">
    <color rgba="0 0 0.8 1"/>
  </material>
  <material name="black">
    <color rgba="0 0 0 1"/>
  </material>
  <material name="white">
    <color rgba="1 1 1 1"/>
  </material>
  <link name="body">
    <visual>
      <origin rpy="1.5707963267948966 0 0" xyz="-0.10 0.1385 -0.05"/>
      <geometry>
        <mesh filename="/home/evence/code_file/ros2_ws/orthrus/install/orthrus_gazebo/share/orthrus_gazebo/models/orthrus/meshes/body.STL"/>
      </geometry>
      <material name="blue"/>
    </visual>
    <collision>
      <origin rpy="1.5707963267948966 0 0" xyz="-0.10 0.1385 -0.05"/>
      <geometry>
        <mesh filename="/home/evence/code_file/ros2_ws/orthrus/install/orthrus_gazebo/share/orthrus_gazebo/models/orthrus/meshes/body.STL"/>
      </geometry>
    </collision>
    <inertial>
      <mass value="10"/>
      <inertia ixx="1.0" ixy="0.0" ixz="0.0" iyy="1.0" iyz="0.0" izz="1.0"/>
    </inertial>
  </link>
  <link name="hip_RF">
    <visual>
      <origin rpy="0 0 0" xyz="-0.02 -0.05 -0.05"/>
      <geometry>
        <mesh filename="/home/evence/code_file/ros2_ws/orthrus/install/orthrus_gazebo/share/orthrus_gazebo/models/orthrus/meshes/hip.STL"/>
      </geometry>
      <material name="black"/>
    </visual>
    <collision>
      <origin rpy="0 0 0" xyz="-0.02 -0.05 -0.05"/>
      <geometry>
        <mesh filename="/home/evence/code_file/ros2_ws/orthrus/install/orthrus_gazebo/share/orthrus_gazebo/models/orthrus/meshes/hip.STL"/>
      </geometry>
    </collision>
    <inertial>
      <mass value="1"/>
      <inertia ixx="1.0" ixy="0.0" ixz="0.0" iyy="1.0" iyz="0.0" izz="1.0"/>
    </inertial>
  </link>
  <joint name="hip_RF_joint" type="revolute">
    <axis xyz="0 0 1"/>
    <parent link="body"/>
    <child link="hip_RF"/>
    <dynamics damping="0.5" friction="0.1"/>
    <limit effort="35.0" lower="-1.5707963267948966" upper="1.5707963267948966" velocity="3.141592653589793"/>
    <origin rpy="-1.5707963267948966 3.141592653589793 3.141592653589793" xyz="0.05 0.20 0"/>
  </joint>
  <link name="hip_LF">
    <visual>
      <origin rpy="0 0 0" xyz="-0.02 -0.05 -0.05"/>
      <geometry>
        <mesh filename="/home/evence/code_file/ros2_ws/orthrus/install/orthrus_gazebo/share/orthrus_gazebo/models/orthrus/meshes/hip.STL"/>
      </geometry>
      <material name="black"/>
    </visual>
    <collision>
      <origin rpy="0 0 0" xyz="-0.02 -0.05 -0.05"/>
      <geometry>
        <mesh filename="/home/evence/code_file/ros2_ws/orthrus/install/orthrus_gazebo/share/orthrus_gazebo/models/orthrus/meshes/hip.STL"/>
      </geometry>
    </collision>
    <inertial>
      <mass value="1"/>
      <inertia ixx="1.0" ixy="0.0" ixz="0.0" iyy="1.0" iyz="0.0" izz="1.0"/>
    </inertial>
  </link>
  <joint name="hip_LF_joint" type="revolute">
    <axis xyz="0 0 1"/>
    <parent link="body"/>
    <child link="hip_LF"/>
    <dynamics damping="0.5" friction="0.1"/>
    <limit effort="35.0" lower="-1.5707963267948966" upper="1.5707963267948966" velocity="3.141592653589793"/>
    <origin rpy="1.5707963267948966 3.141592653589793 0" xyz="-0.05 0.20 0"/>
  </joint>
  <link name="hip_RB">
    <visual>
      <origin rpy="0 0 0" xyz="-0.02 -0.05 -0.05"/>
      <geometry>
        <mesh filename="/home/evence/code_file/ros2_ws/orthrus/install/orthrus_gazebo/share/orthrus_gazebo/models/orthrus/meshes/hip.STL"/>
      </geometry>
      <material name="black"/>
    </visual>
    <collision>
      <origin rpy="0 0 0" xyz="-0.02 -0.05 -0.05"/>
      <geometry>
        <mesh filename="/home/evence/code_file/ros2_ws/orthrus/install/orthrus_gazebo/share/orthrus_gazebo/models/orthrus/meshes/hip.STL"/>
      </geometry>
    </collision>
    <inertial>
      <mass value="1"/>
      <inertia ixx="1.0" ixy="0.0" ixz="0.0" iyy="1.0" iyz="0.0" izz="1.0"/>
    </inertial>
  </link>
  <joint name="hip_RB_joint" type="revolute">
    <axis xyz="0 0 1"/>
    <parent link="body"/>
    <child link="hip_RB"/>
    <dynamics damping="0.5" friction="0.1"/>
    <limit effort="35.0" lower="-1.5707963267948966" upper="1.5707963267948966" velocity="3.141592653589793"/>
    <origin rpy="1.5707963267948966 3.141592653589793 3.141592653589793" xyz="0.05 -0.20 0"/>
  </joint>
  <link name="hip_LB">
    <visual>
      <origin rpy="0 0 0" xyz="-0.02 -0.05 -0.05"/>
      <geometry>
        <mesh filename="/home/evence/code_file/ros2_ws/orthrus/install/orthrus_gazebo/share/orthrus_gazebo/models/orthrus/meshes/hip.STL"/>
      </geometry>
      <material name="black"/>
    </visual>
    <collision>
      <origin rpy="0 0 0" xyz="-0.02 -0.05 -0.05"/>
      <geometry>
        <mesh filename="/home/evence/code_file/ros2_ws/orthrus/install/orthrus_gazebo/share/orthrus_gazebo/models/orthrus/meshes/hip.STL"/>
      </geometry>
    </collision>
    <inertial>
      <mass value="1"/>
      <inertia ixx="1.0" ixy="0.0" ixz="0.0" iyy="1.0" iyz="0.0" izz="1.0"/>
    </inertial>
  </link>
  <joint name="hip_LB_joint" type="revolute">
    <axis xyz="0 0 1"/>
    <parent link="body"/>
    <child link="hip_LB"/>
    <dynamics damping="0.5" friction="0.1"/>
    <limit effort="35.0" lower="-1.5707963267948966" upper="1.5707963267948966" velocity="3.141592653589793"/>
    <origin rpy="-1.5707963267948966 3.141592653589793 0" xyz="-0.05 -0.20 0"/>
  </joint>
  <link name="leg1_RF">
    <visual>
      <origin rpy="0 0 0" xyz="0 -0.2 -0.05"/>
      <geometry>
        <mesh filename="/home/evence/code_file/ros2_ws/orthrus/install/orthrus_gazebo/share/orthrus_gazebo/models/orthrus/meshes/leg1.STL"/>
      </geometry>
      <material name="black"/>
    </visual>
    <collision>
      <origin rpy="0 0 0" xyz="0 -0.2 -0.05"/>
      <geometry>
        <mesh filename="/home/evence/code_file/ros2_ws/orthrus/install/orthrus_gazebo/share/orthrus_gazebo/models/orthrus/meshes/leg1.STL"/>
      </geometry>
    </collision>
    <inertial>
      <mass value="1"/>
      <inertia ixx="1.0" ixy="0.0" ixz="0.0" iyy="1.0" iyz="0.0" izz="1.0"/>
    </inertial>
  </link>
  <joint name="leg1_RF_joint" type="revolute">
    <axis xyz="1 0 0"/>
    <parent link="hip_RF"/>
    <child link="leg1_RF"/>
    <dynamics damping="0.5" friction="0.1"/>
    <limit effort="35.0" lower="-2.0943951023931953" upper="2.0943951023931953" velocity="3.141592653589793"/>
    <origin rpy="-1.5707963267948966 0 0" xyz="0.05 0 0"/>
  </joint>
  <link name="leg1_LF">
    <visual>
      <origin rpy="0 0 0" xyz="0 -0.2 -0.05"/>
      <geometry>
        <mesh filename="/home/evence/code_file/ros2_ws/orthrus/install/orthrus_gazebo/share/orthrus_gazebo/models/orthrus/meshes/leg1.STL"/>
      </geometry>
      <material name="black"/>
    </visual>
    <collision>
      <origin rpy="0 0 0" xyz="0 -0.2 -0.05"/>
      <geometry>
        <mesh filename="/home/evence/code_file/ros2_ws/orthrus/install/orthrus_gazebo/share/orthrus_gazebo/models/orthrus/meshes/leg1.STL"/>
      </geometry>
    </collision>
    <inertial>
      <mass value="1"/>
      <inertia ixx="1.0" ixy="0.0" ixz="0.0" iyy="1.0" iyz="0.0" izz="1.0"/>
    </inertial>
  </link>
  <joint name="leg1_LF_joint" type="revolute">
    <axis xyz="1 0 0"/>
    <parent link="hip_LF"/>
    <child link="leg1_LF"/>
    <dynamics damping="0.5" friction="0.1"/>
    <limit effort="35.0" lower="-2.0943951023931953" upper="2.0943951023931953" velocity="3.141592653589793"/>
    <origin rpy="-1.5707963267948966 0 0" xyz="0.05 0 0"/>
  </joint>
  <link name="leg1_RB">
    <visual>
      <origin rpy="0 0 0" xyz="0 -0.2 -0.05"/>
      <geometry>
        <mesh filename="/home/evence/code_file/ros2_ws/orthrus/install/orthrus_gazebo/share/orthrus_gazebo/models/orthrus/meshes/leg1.STL"/>
      </geometry>
      <material name="black"/>
    </visual>
    <collision>
      <origin rpy="0 0 0" xyz="0 -0.2 -0.05"/>
      <geometry>
        <mesh filename="/home/evence/code_file/ros2_ws/orthrus/install/orthrus_gazebo/share/orthrus_gazebo/models/orthrus/meshes/leg1.STL"/>
      </geometry>
    </collision>
    <inertial>
      <mass value="1"/>
      <inertia ixx="1.0" ixy="0.0" ixz="0.0" iyy="1.0" iyz="0.0" izz="1.0"/>
    </inertial>
  </link>
  <joint name="leg1_RB_joint" type="revolute">
    <axis xyz="1 0 0"/>
    <parent link="hip_RB"/>
    <child link="leg1_RB"/>
    <dynamics damping="0.5" friction="0.1"/>
    <limit effort="35.0" lower="-2.0943951023931953" upper="2.0943951023931953" velocity="3.141592653589793"/>
    <origin rpy="1.5707963267948966 0 0" xyz="0.05 0 0"/>
  </joint>
  <link name="leg1_LB">
    <visual>
      <origin rpy="0 0 0" xyz="0 -0.2 -0.05"/>
      <geometry>
        <mesh filename="/home/evence/code_file/ros2_ws/orthrus/install/orthrus_gazebo/share/orthrus_gazebo/models/orthrus/meshes/leg1.STL"/>
      </geometry>
      <material name="black"/>
    </visual>
    <collision>
      <origin rpy="0 0 0" xyz="0 -0.2 -0.05"/>
      <geometry>
        <mesh filename="/home/evence/code_file/ros2_ws/orthrus/install/orthrus_gazebo/share/orthrus_gazebo/models/orthrus/meshes/leg1.STL"/>
      </geometry>
    </collision>
    <inertial>
      <mass value="1"/>
      <inertia ixx="1.0" ixy="0.0" ixz="0.0" iyy="1.0" iyz="0.0" izz="1.0"/>
    </inertial>
  </link>
  <joint name="leg1_LB_joint" type="revolute">
    <axis xyz="1 0 0"/>
    <parent link="hip_LB"/>
    <child link="leg1_LB"/>
    <dynamics damping="0.5" friction="0.1"/>
    <limit effort="35.0" lower="-2.0943951023931953" upper="2.0943951023931953" velocity="3.141592653589793"/>
    <origin rpy="1.5707963267948966 0 0" xyz="0.05 0 0"/>
  </joint>
  <link name="leg2_LF">
    <visual>
      <origin rpy="0 0 0" xyz="-0.025 -0.025 -0.225"/>
      <geometry>
        <mesh filename="/home/evence/code_file/ros2_ws/orthrus/install/orthrus_gazebo/share/orthrus_gazebo/models/orthrus/meshes/leg2.STL"/>
      </geometry>
      <material name="black"/>
    </visual>
    <collision>
      <origin rpy="0 0 0" xyz="-0.025 -0.025 -0.225"/>
      <geometry>
        <mesh filename="/home/evence/code_file/ros2_ws/orthrus/install/orthrus_gazebo/share/orthrus_gazebo/models/orthrus/meshes/leg2.STL"/>
      </geometry>
    </collision>
    <inertial>
      <mass value="1"/>
      <inertia ixx="1.0" ixy="0.0" ixz="0.0" iyy="1.0" iyz="0.0" izz="1.0"/>
    </inertial>
  </link>
  <joint name="leg2_LF_joint" type="revolute">
    <axis xyz="1 0 0"/>
    <parent link="leg1_LF"/>
    <child link="leg2_LF"/>
    <dynamics damping="0.5" friction="0.1"/>
    <origin rpy="2.0943951023931953 0 0" xyz="0.035 -0.18 0"/>
    <limit effort="35.0" lower="-0.2617993877991494" upper="2.0943951023931953" velocity="3.141592653589793"/>
  </joint>
  <link name="leg2_RF">
    <visual>
      <origin rpy="0 0 0" xyz="-0.025 -0.025 -0.225"/>
      <geometry>
        <mesh filename="/home/evence/code_file/ros2_ws/orthrus/install/orthrus_gazebo/share/orthrus_gazebo/models/orthrus/meshes/leg2.STL"/>
      </geometry>
      <material name="black"/>
    </visual>
    <collision>
      <origin rpy="0 0 0" xyz="-0.025 -0.025 -0.225"/>
      <geometry>
        <mesh filename="/home/evence/code_file/ros2_ws/orthrus/install/orthrus_gazebo/share/orthrus_gazebo/models/orthrus/meshes/leg2.STL"/>
      </geometry>
    </collision>
    <inertial>
      <mass value="1"/>
      <inertia ixx="1.0" ixy="0.0" ixz="0.0" iyy="1.0" iyz="0.0" izz="1.0"/>
    </inertial>
  </link>
  <joint name="leg2_RF_joint" type="revolute">
    <axis xyz="1 0 0"/>
    <parent link="leg1_RF"/>
    <child link="leg2_RF"/>
    <dynamics damping="0.5" friction="0.1"/>
    <origin rpy="1.0471975511965976 0 0" xyz="0.035 -0.18 0"/>
    <limit effort="35.0" lower="-2.0943951023931953" upper="0.2617993877991494" velocity="3.141592653589793"/>
  </joint>
  <link name="leg2_LB">
    <visual>
      <origin rpy="0 0 0" xyz="-0.025 -0.025 -0.225"/>
      <geometry>
        <mesh filename="/home/evence/code_file/ros2_ws/orthrus/install/orthrus_gazebo/share/orthrus_gazebo/models/orthrus/meshes/leg2.STL"/>
      </geometry>
      <material name="black"/>
    </visual>
    <collision>
      <origin rpy="0 0 0" xyz="-0.025 -0.025 -0.225"/>
      <geometry>
        <mesh filename="/home/evence/code_file/ros2_ws/orthrus/install/orthrus_gazebo/share/orthrus_gazebo/models/orthrus/meshes/leg2.STL"/>
      </geometry>
    </collision>
    <inertial>
      <mass value="1"/>
      <inertia ixx="1.0" ixy="0.0" ixz="0.0" iyy="1.0" iyz="0.0" izz="1.0"/>
    </inertial>
  </link>
  <joint name="leg2_LB_joint" type="revolute">
    <axis xyz="1 0 0"/>
    <parent link="leg1_LB"/>
    <child link="leg2_LB"/>
    <dynamics damping="0.5" friction="0.1"/>
    <origin rpy="2.0943951023931953 0 0" xyz="0.035 -0.18 0"/>
    <limit effort="35.0" lower="-0.2617993877991494" upper="2.0943951023931953" velocity="3.141592653589793"/>
  </joint>
  <link name="leg2_RB">
    <visual>
      <origin rpy="0 0 0" xyz="-0.025 -0.025 -0.225"/>
      <geometry>
        <mesh filename="/home/evence/code_file/ros2_ws/orthrus/install/orthrus_gazebo/share/orthrus_gazebo/models/orthrus/meshes/leg2.STL"/>
      </geometry>
      <material name="black"/>
    </visual>
    <collision>
      <origin rpy="0 0 0" xyz="-0.025 -0.025 -0.225"/>
      <geometry>
        <mesh filename="/home/evence/code_file/ros2_ws/orthrus/install/orthrus_gazebo/share/orthrus_gazebo/models/orthrus/meshes/leg2.STL"/>
      </geometry>
    </collision>
    <inertial>
      <mass value="1"/>
      <inertia ixx="1.0" ixy="0.0" ixz="0.0" iyy="1.0" iyz="0.0" izz="1.0"/>
    </inertial>
  </link>
  <joint name="leg2_RB_joint" type="revolute">
    <axis xyz="1 0 0"/>
    <parent link="leg1_RB"/>
    <child link="leg2_RB"/>
    <dynamics damping="0.5" friction="0.1"/>
    <origin rpy="1.0471975511965976 0 0" xyz="0.035 -0.18 0"/>
    <limit effort="35.0" lower="-2.0943951023931953" upper="0.2617993877991494" velocity="3.141592653589793"/>
  </joint>
  <ros2_control name="GazeboSystem" type="system">
    <hardware>
      <plugin>gazebo_ros2_control/GazeboSystem</plugin>
    </hardware>
    <joint name="hip_RF_joint">
      <command_interface name="position">
        <param name="min">-1.5707963267948966</param>
        <param name="max">1.5707963267948966</param>
      </command_interface>
      <state_interface name="position"/>
      <state_interface name="velocity"/>
      <state_interface name="effort"/>
    </joint>
  </ros2_control>
  <gazebo>
    <plugin filename="libgazebo_ros2_control.so" name="gazebo_ros2_control">
      <robot_sim_type>gazebo_ros2_control/GazeboSystem</robot_sim_type>
      <parameters>/home/evence/code_file/ros2_ws/orthrus/src/orthrus_ros2_pack/orthrus_sim/orthrus_gazebo/config/orthrus.yaml</parameters>
    </plugin>
  </gazebo>
</robot>
