<robot name="orthrus_base"
  xmlns:xacro="http://ros.org/wiki/xacro">

  <material name="blue">
    <color rgba="0 0 0.8 1"/>
  </material>

  <material name="black">
    <color rgba="0 0 0 1"/>
  </material>

  <material name="white">
    <color rgba="1 1 1 1"/>
  </material>

  <link name="base">
    <visual>
      <origin xyz="-0.1385 -0.10 -0.05" rpy="${pi/2} 0 ${pi/2}" />
      <geometry>
        <mesh filename="${meshes_folder}/body.STL"/>
      </geometry>
      <material name="blue"/>
    </visual>
    <collision>
      <origin xyz="-0.1385 -0.10 -0.05" rpy="${pi/2} 0 ${pi/2}" />
      <geometry>
        <mesh filename="${meshes_folder}/body.STL"/>
      </geometry>
    </collision>
    <inertial>
      <mass value="7"/>
      <inertia ixx="2.4616377" ixy="0" ixz="0" iyy="4.9950395" iyz="0" izz="6.4183150" />
    </inertial>
  </link>

  <xacro:macro name="HAA" params="prefix">
    <link name="${prefix}_HAA_link">
      <visual>
        <origin xyz="-0.02 -0.05 -0.05" rpy="0 0 0" />
        <geometry>
          <mesh filename="${meshes_folder}/hip.STL"/>
        </geometry>
        <material name="black"/>
      </visual>
      <collision>
        <origin xyz="-0.02 -0.05 -0.05" rpy="0 0 0" />
        <geometry>
          <mesh filename="${meshes_folder}/hip.STL"/>
        </geometry>
      </collision>
      <inertial>
        <origin xyz="0.01493 0.00159 0.00" rpy="0 0 0" />
        <mass value="0.7"/>
        <inertia ixx="-0.084" ixy="0.0" ixz="0.996" iyy="-1.0" iyz="0.0" izz="0.084" />
      </inertial>
    </link>

    <joint name="${prefix}_HAA" type="revolute">
      <axis xyz="0 0 1"/>
      <parent link="base"/>
      <child link="${prefix}_HAA_link"/>
      <dynamics damping="0.4" friction="0.3"/>
      <limit effort="35.0" lower="-${pi/2}" upper="${pi/2}" velocity="${pi}"/>
      <xacro:if value="${prefix == 'LF'}">
        <origin xyz="0.20 0.05 0" rpy="${pi/2} ${pi} ${-pi/2}" />
      </xacro:if>
      <xacro:if value="${prefix == 'LH'}">
        <origin xyz="-0.20 0.05 0" rpy="-${pi/2} ${pi} ${-pi/2}" />
      </xacro:if>
      <xacro:if value="${prefix == 'RH'}">
        <origin xyz="-0.20 -0.05 0" rpy="${pi/2} ${pi} ${pi/2}" />
      </xacro:if>
      <xacro:if value="${prefix == 'RF'}">
        <origin xyz="0.20 -0.05 0" rpy="-${pi/2} ${pi} ${pi/2}" />
      </xacro:if>
    </joint>
  </xacro:macro>

  <xacro:macro name="HFE" params="prefix">
    <link name="${prefix}_HFE_link">
      <visual>
        <origin xyz="0 -0.2 -0.05" rpy="0 0 0" />
        <geometry>
          <mesh filename="${meshes_folder}/leg1.STL"/>
        </geometry>
        <material name="black"/>
      </visual>
      <collision>
        <origin xyz="0 -0.2 -0.05" rpy="0 0 0" />
        <geometry>
          <mesh filename="${meshes_folder}/leg1.STL"/>
        </geometry>
      </collision>
      <inertial>
        <origin xyz="0.02764 -0.02513 0.00" rpy="0 0 0" />
        <mass value="1"/>
        <inertia ixx="0.4329464" ixy="-0.0830239" ixz=" -0.0000001" iyy="0.1503071" iyz="0.0000001" izz="0.4817994" />
      </inertial>
    </link>

    <joint name="${prefix}_HFE" type="revolute">
      <axis xyz="1 0 0"/>
      <parent link="${prefix}_HAA_link"/>
      <child link="${prefix}_HFE_link"/>
      <dynamics damping="0.4" friction="0.3"/>
      <limit effort="35.0" lower="-${pi*2/3}" upper="${pi*2/3}" velocity="${pi}"/>
      <xacro:if value="${prefix == 'LF'}">
        <origin xyz="0.05 0 0" rpy="-${pi/2} 0 0" />
      </xacro:if>
      <xacro:if value="${prefix == 'LH'}">
        <origin xyz="0.05 0 0" rpy="${pi/2} 0 0" />
      </xacro:if>
      <xacro:if value="${prefix == 'RH'}">
        <origin xyz="0.05 0 0" rpy="${pi/2} 0 0" />
      </xacro:if>
      <xacro:if value="${prefix == 'RF'}">
        <origin xyz="0.05 0 0" rpy="-${pi/2} 0 0" />
      </xacro:if>
    </joint>
  </xacro:macro>

  <xacro:macro name="KFE" params="prefix">
    <link name="${prefix}_KFE_link">
      <visual>
        <origin xyz="-0.025 -0.025 -0.225" rpy="0 0 0" />
        <geometry>
          <mesh filename="${meshes_folder}/leg2.STL"/>
        </geometry>
        <material name="black"/>
      </visual>
      <collision>
        <origin xyz="-0.025 -0.025 -0.225" rpy="0 0 0" />
        <geometry>
          <mesh filename="${meshes_folder}/leg2.STL"/>
        </geometry>
      </collision>
      <inertial>
        <origin xyz="0.00 0.00 -0.12564" rpy="0 0 0" />
        <mass value="0.2"/>
        <inertia ixx="0.4201680" ixy="0" ixz="0" iyy="0.4196489" iyz="0" izz="0.0031965" />
      </inertial>
    </link>

    <joint name="${prefix}_KFE" type="revolute">
      <axis xyz="1 0 0"/>
      <parent link="${prefix}_HFE_link"/>
      <child link="${prefix}_KFE_link"/>
      <dynamics damping="0.4" friction="0.3"/>

      <xacro:if value="${prefix == 'LF'}">
        <origin xyz="0.035 -0.18 0" rpy="${pi*2/3} 0 0" />
        <limit effort="35.0" lower="-${pi*1/12}" upper="${pi*2/3}" velocity="${pi}"/>
      </xacro:if>
      <xacro:if value="${prefix == 'RF'}">
        <origin xyz="0.035 -0.18 0" rpy="${pi*1/3} 0 0" />
        <limit effort="35.0" lower="-${pi*2/3}" upper="${pi*1/12}" velocity="${pi}"/>
      </xacro:if>
      <xacro:if value="${prefix == 'RH'}">
        <origin xyz="0.035 -0.18 0" rpy="${pi*1/3} 0 0" />
        <limit effort="35.0" lower="-${pi*2/3}" upper="${pi*1/12}" velocity="${pi}"/>
      </xacro:if>
      <xacro:if value="${prefix == 'LH'}">
        <origin xyz="0.035 -0.18 0" rpy="${pi*2/3} 0 0" />
        <limit effort="35.0" lower="-${pi*1/12}" upper="${pi*2/3}" velocity="${pi}"/>
      </xacro:if>

    </joint>
  </xacro:macro>

  <xacro:macro name="FOOT" params="prefix">
    <link name="${prefix}_FOOT_link">
    </link>

    <joint name="${prefix}_FOOT" type="fixed">
      <axis xyz="1 0 0"/>
      <parent link="${prefix}_KFE_link"/>
      <child link="${prefix}_FOOT_link"/>
      <origin xyz="0.0 0.0 -0.2" rpy="0 0 0" />
    </joint>
  </xacro:macro>

  <xacro:macro name="ros2_HAA_joint" params="prefix">
    <joint name="${prefix}_HAA">
      <command_interface name="effort">
        <param name="min">-35</param>
        <param name="max">35</param>
      </command_interface>
      <state_interface name="position"/>
      <state_interface name="velocity"/>
      <state_interface name="effort"/>
    </joint>
  </xacro:macro>

  <xacro:macro name="ros2_HFE_joint" params="prefix">
    <joint name="${prefix}_HFE">
      <command_interface name="effort">
        <param name="min">-35</param>
        <param name="max">35</param>
      </command_interface>
      <state_interface name="position"/>
      <state_interface name="velocity"/>
      <state_interface name="effort"/>
    </joint>
  </xacro:macro>

  <xacro:macro name="ros2_KFE_joint" params="prefix">
    <joint name="${prefix}_KFE">
      <command_interface name="effort">
        <param name="min">-35</param>
        <param name="max">35</param>
      </command_interface>
      <state_interface name="position"/>
      <state_interface name="velocity"/>
      <state_interface name="effort"/>
    </joint>
  </xacro:macro>

  <xacro:macro name="ros2_FOOT_joint" params="prefix">
    <joint name="${prefix}_FOOT">
    </joint>
  </xacro:macro>

</robot>


