<?xml version="1.0" ?>
<!-- =================================================================================== -->
<!-- |    This document was autogenerated by xacro from orthrus_real.urdf.xacro        | -->
<!-- |    EDITING THIS FILE BY HAND IS NOT RECOMMENDED                                 | -->
<!-- =================================================================================== -->
<robot name="orthrus">
  <material name="blue">
    <color rgba="0 0 0.8 1"/>
  </material>
  <material name="black">
    <color rgba="0 0 0 1"/>
  </material>
  <material name="white">
    <color rgba="1 1 1 1"/>
  </material>
  <link name="base">
    <visual>
      <origin rpy="1.5707963267948966 0 1.5707963267948966" xyz="-0.1385 -0.10 -0.05"/>
      <geometry>
        <mesh filename="file:////home/evence/code_file/ros2_ws/orthrus/install/orthrus_interfaces/share/orthrus_interfaces/models/orthrus/meshes/body.STL"/>
      </geometry>
      <material name="blue"/>
    </visual>
    <collision>
      <origin rpy="1.5707963267948966 0 1.5707963267948966" xyz="-0.1385 -0.10 -0.05"/>
      <geometry>
        <mesh filename="file:////home/evence/code_file/ros2_ws/orthrus/install/orthrus_interfaces/share/orthrus_interfaces/models/orthrus/meshes/body.STL"/>
      </geometry>
    </collision>
    <inertial>
      <mass value="7"/>
      <inertia ixx="2.4616377" ixy="0" ixz="0" iyy="4.9950395" iyz="0" izz="6.4183150"/>
    </inertial>
  </link>
  <link name="LF_HAA_link">
    <visual>
      <origin rpy="0 0 0" xyz="-0.02 -0.05 -0.05"/>
      <geometry>
        <mesh filename="file:////home/evence/code_file/ros2_ws/orthrus/install/orthrus_interfaces/share/orthrus_interfaces/models/orthrus/meshes/hip.STL"/>
      </geometry>
      <material name="black"/>
    </visual>
    <collision>
      <origin rpy="0 0 0" xyz="-0.02 -0.05 -0.05"/>
      <geometry>
        <mesh filename="file:////home/evence/code_file/ros2_ws/orthrus/install/orthrus_interfaces/share/orthrus_interfaces/models/orthrus/meshes/hip.STL"/>
      </geometry>
    </collision>
    <inertial>
      <origin rpy="0 0 0" xyz="0.01493 0.00159 0.00"/>
      <mass value="0.7"/>
      <inertia ixx="-0.084" ixy="0.0" ixz="0.996" iyy="-1.0" iyz="0.0" izz="0.084"/>
    </inertial>
  </link>
  <joint name="LF_HAA" type="revolute">
    <axis xyz="0 0 1"/>
    <parent link="base"/>
    <child link="LF_HAA_link"/>
    <dynamics damping="0.4" friction="0.3"/>
    <limit effort="35.0" lower="-1.5707963267948966" upper="1.5707963267948966" velocity="3.141592653589793"/>
    <origin rpy="1.5707963267948966 3.141592653589793 -1.5707963267948966" xyz="0.20 0.05 0"/>
  </joint>
  <link name="LF_HFE_link">
    <visual>
      <origin rpy="0 0 0" xyz="0 -0.2 -0.05"/>
      <geometry>
        <mesh filename="file:////home/evence/code_file/ros2_ws/orthrus/install/orthrus_interfaces/share/orthrus_interfaces/models/orthrus/meshes/leg1.STL"/>
      </geometry>
      <material name="black"/>
    </visual>
    <collision>
      <origin rpy="0 0 0" xyz="0 -0.2 -0.05"/>
      <geometry>
        <mesh filename="file:////home/evence/code_file/ros2_ws/orthrus/install/orthrus_interfaces/share/orthrus_interfaces/models/orthrus/meshes/leg1.STL"/>
      </geometry>
    </collision>
    <inertial>
      <origin rpy="0 0 0" xyz="0.02764 -0.02513 0.00"/>
      <mass value="1"/>
      <inertia ixx="0.4329464" ixy="-0.0830239" ixz=" -0.0000001" iyy="0.1503071" iyz="0.0000001" izz="0.4817994"/>
    </inertial>
  </link>
  <joint name="LF_HFE" type="revolute">
    <axis xyz="1 0 0"/>
    <parent link="LF_HAA_link"/>
    <child link="LF_HFE_link"/>
    <dynamics damping="0.4" friction="0.3"/>
    <limit effort="35.0" lower="-2.0943951023931953" upper="2.0943951023931953" velocity="3.141592653589793"/>
    <origin rpy="-1.5707963267948966 0 0" xyz="0.05 0 0"/>
  </joint>
  <link name="LF_KFE_link">
    <visual>
      <origin rpy="0 0 0" xyz="-0.025 -0.025 -0.225"/>
      <geometry>
        <mesh filename="file:////home/evence/code_file/ros2_ws/orthrus/install/orthrus_interfaces/share/orthrus_interfaces/models/orthrus/meshes/leg2.STL"/>
      </geometry>
      <material name="black"/>
    </visual>
    <collision>
      <origin rpy="0 0 0" xyz="-0.025 -0.025 -0.225"/>
      <geometry>
        <mesh filename="file:////home/evence/code_file/ros2_ws/orthrus/install/orthrus_interfaces/share/orthrus_interfaces/models/orthrus/meshes/leg2.STL"/>
      </geometry>
    </collision>
    <inertial>
      <origin rpy="0 0 0" xyz="0.00 0.00 -0.12564"/>
      <mass value="0.2"/>
      <inertia ixx="0.4201680" ixy="0" ixz="0" iyy="0.4196489" iyz="0" izz="0.0031965"/>
    </inertial>
  </link>
  <joint name="LF_KFE" type="revolute">
    <axis xyz="1 0 0"/>
    <parent link="LF_HFE_link"/>
    <child link="LF_KFE_link"/>
    <dynamics damping="0.4" friction="0.3"/>
    <origin rpy="2.0943951023931953 0 0" xyz="0.035 -0.18 0"/>
    <limit effort="35.0" lower="-0.2617993877991494" upper="2.0943951023931953" velocity="3.141592653589793"/>
  </joint>
  <link name="LF_FOOT_link">
    </link>
  <joint name="LF_FOOT" type="fixed">
    <axis xyz="1 0 0"/>
    <parent link="LF_KFE_link"/>
    <child link="LF_FOOT_link"/>
    <origin rpy="0 0 0" xyz="0.0 0.0 -0.2"/>
  </joint>
  <link name="LH_HAA_link">
    <visual>
      <origin rpy="0 0 0" xyz="-0.02 -0.05 -0.05"/>
      <geometry>
        <mesh filename="file:////home/evence/code_file/ros2_ws/orthrus/install/orthrus_interfaces/share/orthrus_interfaces/models/orthrus/meshes/hip.STL"/>
      </geometry>
      <material name="black"/>
    </visual>
    <collision>
      <origin rpy="0 0 0" xyz="-0.02 -0.05 -0.05"/>
      <geometry>
        <mesh filename="file:////home/evence/code_file/ros2_ws/orthrus/install/orthrus_interfaces/share/orthrus_interfaces/models/orthrus/meshes/hip.STL"/>
      </geometry>
    </collision>
    <inertial>
      <origin rpy="0 0 0" xyz="0.01493 0.00159 0.00"/>
      <mass value="0.7"/>
      <inertia ixx="-0.084" ixy="0.0" ixz="0.996" iyy="-1.0" iyz="0.0" izz="0.084"/>
    </inertial>
  </link>
  <joint name="LH_HAA" type="revolute">
    <axis xyz="0 0 1"/>
    <parent link="base"/>
    <child link="LH_HAA_link"/>
    <dynamics damping="0.4" friction="0.3"/>
    <limit effort="35.0" lower="-1.5707963267948966" upper="1.5707963267948966" velocity="3.141592653589793"/>
    <origin rpy="-1.5707963267948966 3.141592653589793 -1.5707963267948966" xyz="-0.20 0.05 0"/>
  </joint>
  <link name="LH_HFE_link">
    <visual>
      <origin rpy="0 0 0" xyz="0 -0.2 -0.05"/>
      <geometry>
        <mesh filename="file:////home/evence/code_file/ros2_ws/orthrus/install/orthrus_interfaces/share/orthrus_interfaces/models/orthrus/meshes/leg1.STL"/>
      </geometry>
      <material name="black"/>
    </visual>
    <collision>
      <origin rpy="0 0 0" xyz="0 -0.2 -0.05"/>
      <geometry>
        <mesh filename="file:////home/evence/code_file/ros2_ws/orthrus/install/orthrus_interfaces/share/orthrus_interfaces/models/orthrus/meshes/leg1.STL"/>
      </geometry>
    </collision>
    <inertial>
      <origin rpy="0 0 0" xyz="0.02764 -0.02513 0.00"/>
      <mass value="1"/>
      <inertia ixx="0.4329464" ixy="-0.0830239" ixz=" -0.0000001" iyy="0.1503071" iyz="0.0000001" izz="0.4817994"/>
    </inertial>
  </link>
  <joint name="LH_HFE" type="revolute">
    <axis xyz="1 0 0"/>
    <parent link="LH_HAA_link"/>
    <child link="LH_HFE_link"/>
    <dynamics damping="0.4" friction="0.3"/>
    <limit effort="35.0" lower="-2.0943951023931953" upper="2.0943951023931953" velocity="3.141592653589793"/>
    <origin rpy="1.5707963267948966 0 0" xyz="0.05 0 0"/>
  </joint>
  <link name="LH_KFE_link">
    <visual>
      <origin rpy="0 0 0" xyz="-0.025 -0.025 -0.225"/>
      <geometry>
        <mesh filename="file:////home/evence/code_file/ros2_ws/orthrus/install/orthrus_interfaces/share/orthrus_interfaces/models/orthrus/meshes/leg2.STL"/>
      </geometry>
      <material name="black"/>
    </visual>
    <collision>
      <origin rpy="0 0 0" xyz="-0.025 -0.025 -0.225"/>
      <geometry>
        <mesh filename="file:////home/evence/code_file/ros2_ws/orthrus/install/orthrus_interfaces/share/orthrus_interfaces/models/orthrus/meshes/leg2.STL"/>
      </geometry>
    </collision>
    <inertial>
      <origin rpy="0 0 0" xyz="0.00 0.00 -0.12564"/>
      <mass value="0.2"/>
      <inertia ixx="0.4201680" ixy="0" ixz="0" iyy="0.4196489" iyz="0" izz="0.0031965"/>
    </inertial>
  </link>
  <joint name="LH_KFE" type="revolute">
    <axis xyz="1 0 0"/>
    <parent link="LH_HFE_link"/>
    <child link="LH_KFE_link"/>
    <dynamics damping="0.4" friction="0.3"/>
    <origin rpy="2.0943951023931953 0 0" xyz="0.035 -0.18 0"/>
    <limit effort="35.0" lower="-0.2617993877991494" upper="2.0943951023931953" velocity="3.141592653589793"/>
  </joint>
  <link name="LH_FOOT_link">
    </link>
  <joint name="LH_FOOT" type="fixed">
    <axis xyz="1 0 0"/>
    <parent link="LH_KFE_link"/>
    <child link="LH_FOOT_link"/>
    <origin rpy="0 0 0" xyz="0.0 0.0 -0.2"/>
  </joint>
  <link name="RF_HAA_link">
    <visual>
      <origin rpy="0 0 0" xyz="-0.02 -0.05 -0.05"/>
      <geometry>
        <mesh filename="file:////home/evence/code_file/ros2_ws/orthrus/install/orthrus_interfaces/share/orthrus_interfaces/models/orthrus/meshes/hip.STL"/>
      </geometry>
      <material name="black"/>
    </visual>
    <collision>
      <origin rpy="0 0 0" xyz="-0.02 -0.05 -0.05"/>
      <geometry>
        <mesh filename="file:////home/evence/code_file/ros2_ws/orthrus/install/orthrus_interfaces/share/orthrus_interfaces/models/orthrus/meshes/hip.STL"/>
      </geometry>
    </collision>
    <inertial>
      <origin rpy="0 0 0" xyz="0.01493 0.00159 0.00"/>
      <mass value="0.7"/>
      <inertia ixx="-0.084" ixy="0.0" ixz="0.996" iyy="-1.0" iyz="0.0" izz="0.084"/>
    </inertial>
  </link>
  <joint name="RF_HAA" type="revolute">
    <axis xyz="0 0 1"/>
    <parent link="base"/>
    <child link="RF_HAA_link"/>
    <dynamics damping="0.4" friction="0.3"/>
    <limit effort="35.0" lower="-1.5707963267948966" upper="1.5707963267948966" velocity="3.141592653589793"/>
    <origin rpy="-1.5707963267948966 3.141592653589793 1.5707963267948966" xyz="0.20 -0.05 0"/>
  </joint>
  <link name="RF_HFE_link">
    <visual>
      <origin rpy="0 0 0" xyz="0 -0.2 -0.05"/>
      <geometry>
        <mesh filename="file:////home/evence/code_file/ros2_ws/orthrus/install/orthrus_interfaces/share/orthrus_interfaces/models/orthrus/meshes/leg1.STL"/>
      </geometry>
      <material name="black"/>
    </visual>
    <collision>
      <origin rpy="0 0 0" xyz="0 -0.2 -0.05"/>
      <geometry>
        <mesh filename="file:////home/evence/code_file/ros2_ws/orthrus/install/orthrus_interfaces/share/orthrus_interfaces/models/orthrus/meshes/leg1.STL"/>
      </geometry>
    </collision>
    <inertial>
      <origin rpy="0 0 0" xyz="0.02764 -0.02513 0.00"/>
      <mass value="1"/>
      <inertia ixx="0.4329464" ixy="-0.0830239" ixz=" -0.0000001" iyy="0.1503071" iyz="0.0000001" izz="0.4817994"/>
    </inertial>
  </link>
  <joint name="RF_HFE" type="revolute">
    <axis xyz="1 0 0"/>
    <parent link="RF_HAA_link"/>
    <child link="RF_HFE_link"/>
    <dynamics damping="0.4" friction="0.3"/>
    <limit effort="35.0" lower="-2.0943951023931953" upper="2.0943951023931953" velocity="3.141592653589793"/>
    <origin rpy="-1.5707963267948966 0 0" xyz="0.05 0 0"/>
  </joint>
  <link name="RF_KFE_link">
    <visual>
      <origin rpy="0 0 0" xyz="-0.025 -0.025 -0.225"/>
      <geometry>
        <mesh filename="file:////home/evence/code_file/ros2_ws/orthrus/install/orthrus_interfaces/share/orthrus_interfaces/models/orthrus/meshes/leg2.STL"/>
      </geometry>
      <material name="black"/>
    </visual>
    <collision>
      <origin rpy="0 0 0" xyz="-0.025 -0.025 -0.225"/>
      <geometry>
        <mesh filename="file:////home/evence/code_file/ros2_ws/orthrus/install/orthrus_interfaces/share/orthrus_interfaces/models/orthrus/meshes/leg2.STL"/>
      </geometry>
    </collision>
    <inertial>
      <origin rpy="0 0 0" xyz="0.00 0.00 -0.12564"/>
      <mass value="0.2"/>
      <inertia ixx="0.4201680" ixy="0" ixz="0" iyy="0.4196489" iyz="0" izz="0.0031965"/>
    </inertial>
  </link>
  <joint name="RF_KFE" type="revolute">
    <axis xyz="1 0 0"/>
    <parent link="RF_HFE_link"/>
    <child link="RF_KFE_link"/>
    <dynamics damping="0.4" friction="0.3"/>
    <origin rpy="1.0471975511965976 0 0" xyz="0.035 -0.18 0"/>
    <limit effort="35.0" lower="-2.0943951023931953" upper="0.2617993877991494" velocity="3.141592653589793"/>
  </joint>
  <link name="RF_FOOT_link">
    </link>
  <joint name="RF_FOOT" type="fixed">
    <axis xyz="1 0 0"/>
    <parent link="RF_KFE_link"/>
    <child link="RF_FOOT_link"/>
    <origin rpy="0 0 0" xyz="0.0 0.0 -0.2"/>
  </joint>
  <link name="RH_HAA_link">
    <visual>
      <origin rpy="0 0 0" xyz="-0.02 -0.05 -0.05"/>
      <geometry>
        <mesh filename="file:////home/evence/code_file/ros2_ws/orthrus/install/orthrus_interfaces/share/orthrus_interfaces/models/orthrus/meshes/hip.STL"/>
      </geometry>
      <material name="black"/>
    </visual>
    <collision>
      <origin rpy="0 0 0" xyz="-0.02 -0.05 -0.05"/>
      <geometry>
        <mesh filename="file:////home/evence/code_file/ros2_ws/orthrus/install/orthrus_interfaces/share/orthrus_interfaces/models/orthrus/meshes/hip.STL"/>
      </geometry>
    </collision>
    <inertial>
      <origin rpy="0 0 0" xyz="0.01493 0.00159 0.00"/>
      <mass value="0.7"/>
      <inertia ixx="-0.084" ixy="0.0" ixz="0.996" iyy="-1.0" iyz="0.0" izz="0.084"/>
    </inertial>
  </link>
  <joint name="RH_HAA" type="revolute">
    <axis xyz="0 0 1"/>
    <parent link="base"/>
    <child link="RH_HAA_link"/>
    <dynamics damping="0.4" friction="0.3"/>
    <limit effort="35.0" lower="-1.5707963267948966" upper="1.5707963267948966" velocity="3.141592653589793"/>
    <origin rpy="1.5707963267948966 3.141592653589793 1.5707963267948966" xyz="-0.20 -0.05 0"/>
  </joint>
  <link name="RH_HFE_link">
    <visual>
      <origin rpy="0 0 0" xyz="0 -0.2 -0.05"/>
      <geometry>
        <mesh filename="file:////home/evence/code_file/ros2_ws/orthrus/install/orthrus_interfaces/share/orthrus_interfaces/models/orthrus/meshes/leg1.STL"/>
      </geometry>
      <material name="black"/>
    </visual>
    <collision>
      <origin rpy="0 0 0" xyz="0 -0.2 -0.05"/>
      <geometry>
        <mesh filename="file:////home/evence/code_file/ros2_ws/orthrus/install/orthrus_interfaces/share/orthrus_interfaces/models/orthrus/meshes/leg1.STL"/>
      </geometry>
    </collision>
    <inertial>
      <origin rpy="0 0 0" xyz="0.02764 -0.02513 0.00"/>
      <mass value="1"/>
      <inertia ixx="0.4329464" ixy="-0.0830239" ixz=" -0.0000001" iyy="0.1503071" iyz="0.0000001" izz="0.4817994"/>
    </inertial>
  </link>
  <joint name="RH_HFE" type="revolute">
    <axis xyz="1 0 0"/>
    <parent link="RH_HAA_link"/>
    <child link="RH_HFE_link"/>
    <dynamics damping="0.4" friction="0.3"/>
    <limit effort="35.0" lower="-2.0943951023931953" upper="2.0943951023931953" velocity="3.141592653589793"/>
    <origin rpy="1.5707963267948966 0 0" xyz="0.05 0 0"/>
  </joint>
  <link name="RH_KFE_link">
    <visual>
      <origin rpy="0 0 0" xyz="-0.025 -0.025 -0.225"/>
      <geometry>
        <mesh filename="file:////home/evence/code_file/ros2_ws/orthrus/install/orthrus_interfaces/share/orthrus_interfaces/models/orthrus/meshes/leg2.STL"/>
      </geometry>
      <material name="black"/>
    </visual>
    <collision>
      <origin rpy="0 0 0" xyz="-0.025 -0.025 -0.225"/>
      <geometry>
        <mesh filename="file:////home/evence/code_file/ros2_ws/orthrus/install/orthrus_interfaces/share/orthrus_interfaces/models/orthrus/meshes/leg2.STL"/>
      </geometry>
    </collision>
    <inertial>
      <origin rpy="0 0 0" xyz="0.00 0.00 -0.12564"/>
      <mass value="0.2"/>
      <inertia ixx="0.4201680" ixy="0" ixz="0" iyy="0.4196489" iyz="0" izz="0.0031965"/>
    </inertial>
  </link>
  <joint name="RH_KFE" type="revolute">
    <axis xyz="1 0 0"/>
    <parent link="RH_HFE_link"/>
    <child link="RH_KFE_link"/>
    <dynamics damping="0.4" friction="0.3"/>
    <origin rpy="1.0471975511965976 0 0" xyz="0.035 -0.18 0"/>
    <limit effort="35.0" lower="-2.0943951023931953" upper="0.2617993877991494" velocity="3.141592653589793"/>
  </joint>
  <link name="RH_FOOT_link">
    </link>
  <joint name="RH_FOOT" type="fixed">
    <axis xyz="1 0 0"/>
    <parent link="RH_KFE_link"/>
    <child link="RH_FOOT_link"/>
    <origin rpy="0 0 0" xyz="0.0 0.0 -0.2"/>
  </joint>
  <ros2_control name="OrthrusSystemHardware" type="system">
    <hardware>
      <plugin>orthrus_control/OrthrusSystemHardware</plugin>
    </hardware>
    <joint name="RF_HAA">
      <command_interface name="effort">
        <param name="min">-35</param>
        <param name="max">35</param>
      </command_interface>
      <state_interface name="position"/>
      <state_interface name="velocity"/>
      <state_interface name="effort"/>
    </joint>
    <joint name="RF_HFE">
      <command_interface name="effort">
        <param name="min">-35</param>
        <param name="max">35</param>
      </command_interface>
      <state_interface name="position"/>
      <state_interface name="velocity"/>
      <state_interface name="effort"/>
    </joint>
    <joint name="RF_KFE">
      <command_interface name="effort">
        <param name="min">-35</param>
        <param name="max">35</param>
      </command_interface>
      <state_interface name="position"/>
      <state_interface name="velocity"/>
      <state_interface name="effort"/>
    </joint>
    <joint name="LF_HAA">
      <command_interface name="effort">
        <param name="min">-35</param>
        <param name="max">35</param>
      </command_interface>
      <state_interface name="position"/>
      <state_interface name="velocity"/>
      <state_interface name="effort"/>
    </joint>
    <joint name="LF_HFE">
      <command_interface name="effort">
        <param name="min">-35</param>
        <param name="max">35</param>
      </command_interface>
      <state_interface name="position"/>
      <state_interface name="velocity"/>
      <state_interface name="effort"/>
    </joint>
    <joint name="LF_KFE">
      <command_interface name="effort">
        <param name="min">-35</param>
        <param name="max">35</param>
      </command_interface>
      <state_interface name="position"/>
      <state_interface name="velocity"/>
      <state_interface name="effort"/>
    </joint>
    <joint name="RH_HAA">
      <command_interface name="effort">
        <param name="min">-35</param>
        <param name="max">35</param>
      </command_interface>
      <state_interface name="position"/>
      <state_interface name="velocity"/>
      <state_interface name="effort"/>
    </joint>
    <joint name="RH_HFE">
      <command_interface name="effort">
        <param name="min">-35</param>
        <param name="max">35</param>
      </command_interface>
      <state_interface name="position"/>
      <state_interface name="velocity"/>
      <state_interface name="effort"/>
    </joint>
    <joint name="RH_KFE">
      <command_interface name="effort">
        <param name="min">-35</param>
        <param name="max">35</param>
      </command_interface>
      <state_interface name="position"/>
      <state_interface name="velocity"/>
      <state_interface name="effort"/>
    </joint>
    <joint name="LH_HAA">
      <command_interface name="effort">
        <param name="min">-35</param>
        <param name="max">35</param>
      </command_interface>
      <state_interface name="position"/>
      <state_interface name="velocity"/>
      <state_interface name="effort"/>
    </joint>
    <joint name="LH_HFE">
      <command_interface name="effort">
        <param name="min">-35</param>
        <param name="max">35</param>
      </command_interface>
      <state_interface name="position"/>
      <state_interface name="velocity"/>
      <state_interface name="effort"/>
    </joint>
    <joint name="LH_KFE">
      <command_interface name="effort">
        <param name="min">-35</param>
        <param name="max">35</param>
      </command_interface>
      <state_interface name="position"/>
      <state_interface name="velocity"/>
      <state_interface name="effort"/>
    </joint>
    <sensor name="imu_sensor">
      <state_interface name="orientation.x"/>
      <state_interface name="orientation.y"/>
      <state_interface name="orientation.z"/>
      <state_interface name="orientation.w"/>
      <state_interface name="angular_velocity.x"/>
      <state_interface name="angular_velocity.y"/>
      <state_interface name="angular_velocity.z"/>
      <state_interface name="linear_acceleration.x"/>
      <state_interface name="linear_acceleration.y"/>
      <state_interface name="linear_acceleration.z"/>
    </sensor>
  </ros2_control>
</robot>
