<robot name="orthrus_base"
  xmlns:xacro="http://ros.org/wiki/xacro">

  <material name="blue">
    <color rgba="0 0 0.8 1"/>
  </material>

  <material name="black">
    <color rgba="0 0 0 1"/>
  </material>

  <material name="white">
    <color rgba="1 1 1 1"/>
  </material>

  <link name="base">
    <visual>
      <origin xyz="-0.1385 -0.10 -0.05" rpy="${pi/2} 0 ${pi/2}" />
      <geometry>
        <mesh filename="${meshes_folder}/body.STL"/>
      </geometry>
      <material name="blue"/>
    </visual>
    <collision>
      <origin xyz="-0.1385 -0.10 -0.05" rpy="${pi/2} 0 ${pi/2}" />
      <geometry>
        <mesh filename="${meshes_folder}/body.STL"/>
      </geometry>
    </collision>
    <inertial>
      <origin xyz="-0.010977 0.000003 -0.000477" rpy="0 0 0" />
      <mass value="4.429"/>
      <inertia ixx="1.4923275" ixy="-0.0034837" ixz=" -0.0020438" iyy="5.0690680" iyz="0.0209222" izz="5.7629196" />
    </inertial>
  </link>

  <xacro:macro name="HAA" params="prefix">
    <link name="${prefix}_HAA_link">
      <visual>
        <origin xyz="-0.02 -0.05 -0.05" rpy="0 0 0" />
        <geometry>
          <mesh filename="${meshes_folder}/hip.STL"/>
        </geometry>
        <material name="black"/>
      </visual>
      <collision>
        <origin xyz="-0.02 -0.05 -0.05" rpy="0 0 0" />
        <geometry>
          <mesh filename="${meshes_folder}/hip.STL"/>
        </geometry>
      </collision>
      <inertial>
        <origin xyz="0.01493 0.00159 0.00" rpy="0 0 0" />
        <mass value="0.7"/>
        <inertia ixx="-0.084" ixy="0.0" ixz="0.996" iyy="-1.0" iyz="0.0" izz="0.084" />
      </inertial>
    </link>

    <joint name="${prefix}_HAA" type="revolute">
      <axis xyz="0 0 1"/>
      <parent link="base"/>
      <child link="${prefix}_HAA_link"/>
      <dynamics damping="0.4" friction="0.3"/>
      <limit effort="35.0" lower="-${pi/2}" upper="${pi/2}" velocity="${pi}"/>
      <xacro:if value="${prefix == 'LF'}">
        <origin xyz="0.20 0.05 0" rpy="${pi/2} ${pi} ${-pi/2}" />
      </xacro:if>
      <xacro:if value="${prefix == 'LH'}">
        <origin xyz="-0.20 0.05 0" rpy="-${pi/2} ${pi} ${-pi/2}" />
      </xacro:if>
      <xacro:if value="${prefix == 'RH'}">
        <origin xyz="-0.20 -0.05 0" rpy="${pi/2} ${pi} ${pi/2}" />
      </xacro:if>
      <xacro:if value="${prefix == 'RF'}">
        <origin xyz="0.20 -0.05 0" rpy="-${pi/2} ${pi} ${pi/2}" />
      </xacro:if>
    </joint>
  </xacro:macro>

  <xacro:macro name="HFE" params="prefix">
    <link name="${prefix}_HFE_link">
      <visual>
        <origin xyz="0 -0.2 -0.05" rpy="0 0 0" />
        <geometry>
          <mesh filename="${meshes_folder}/leg1.STL"/>
        </geometry>
        <material name="black"/>
      </visual>
      <collision>
        <origin xyz="0 -0.2 -0.05" rpy="0 0 0" />
        <geometry>
          <mesh filename="${meshes_folder}/leg1.STL"/>
        </geometry>
      </collision>
      <inertial>
        <origin xyz="0.02764 -0.02513 0.00" rpy="0 0 0" />
        <mass value="1"/>
        <inertia ixx="0.4329464" ixy="-0.0830239" ixz=" -0.0000001" iyy="0.1503071" iyz="0.0000001" izz="0.4817994" />
      </inertial>
    </link>

    <joint name="${prefix}_HFE" type="revolute">
      <axis xyz="1 0 0"/>
      <parent link="${prefix}_HAA_link"/>
      <child link="${prefix}_HFE_link"/>
      <dynamics damping="0.4" friction="0.3"/>
      <limit effort="35.0" lower="-${pi*2/3}" upper="${pi*2/3}" velocity="${pi}"/>
      <xacro:if value="${prefix == 'LF'}">
        <origin xyz="0.05 0 0" rpy="-${pi/2} 0 0" />
      </xacro:if>
      <xacro:if value="${prefix == 'LH'}">
        <origin xyz="0.05 0 0" rpy="${pi/2} 0 0" />
      </xacro:if>
      <xacro:if value="${prefix == 'RH'}">
        <origin xyz="0.05 0 0" rpy="${pi/2} 0 0" />
      </xacro:if>
      <xacro:if value="${prefix == 'RF'}">
        <origin xyz="0.05 0 0" rpy="-${pi/2} 0 0" />
      </xacro:if>
    </joint>
  </xacro:macro>

  <xacro:macro name="KFE" params="prefix">
    <link name="${prefix}_KFE_link">
      <visual>
        <origin xyz="-0.025 -0.025 -0.225" rpy="0 0 0" />
        <geometry>
          <mesh filename="${meshes_folder}/leg2.STL"/>
        </geometry>
        <material name="black"/>
      </visual>
      <collision>
        <origin xyz="-0.025 -0.025 -0.225" rpy="0 0 0" />
        <geometry>
          <mesh filename="${meshes_folder}/leg2.STL"/>
        </geometry>
      </collision>
      <inertial>
        <origin xyz="0.00 0.00 -0.12564" rpy="0 0 0" />
        <mass value="0.2"/>
        <inertia ixx="0.4201680" ixy="0" ixz="0" iyy="0.4196489" iyz="0" izz="0.0031965" />
      </inertial>
    </link>

    <joint name="${prefix}_KFE" type="revolute">
      <axis xyz="1 0 0"/>
      <parent link="${prefix}_HFE_link"/>
      <child link="${prefix}_KFE_link"/>
      <dynamics damping="0.4" friction="0.3"/>

      <xacro:if value="${prefix == 'LF'}">
        <origin xyz="0.035 -0.18 0" rpy="${pi*2/3} 0 0" />
        <limit effort="35.0" lower="-${pi*1/12}" upper="${pi*2/3}" velocity="${pi}"/>
      </xacro:if>
      <xacro:if value="${prefix == 'RF'}">
        <origin xyz="0.035 -0.18 0" rpy="${pi*1/3} 0 0" />
        <limit effort="35.0" lower="-${pi*2/3}" upper="${pi*1/12}" velocity="${pi}"/>
      </xacro:if>
      <xacro:if value="${prefix == 'RH'}">
        <origin xyz="0.035 -0.18 0" rpy="${pi*1/3} 0 0" />
        <limit effort="35.0" lower="-${pi*2/3}" upper="${pi*1/12}" velocity="${pi}"/>
      </xacro:if>
      <xacro:if value="${prefix == 'LH'}">
        <origin xyz="0.035 -0.18 0" rpy="${pi*2/3} 0 0" />
        <limit effort="35.0" lower="-${pi*1/12}" upper="${pi*2/3}" velocity="${pi}"/>
      </xacro:if>

    </joint>
  </xacro:macro>

  <xacro:macro name="FOOT" params="prefix">
    <link name="${prefix}_FOOT_link">
    </link>

    <joint name="${prefix}_FOOT" type="fixed">
      <axis xyz="1 0 0"/>
      <parent link="${prefix}_KFE_link"/>
      <child link="${prefix}_FOOT_link"/>
      <origin xyz="0.0 0.0 -0.2" rpy="0 0 0" />
    </joint>
  </xacro:macro>

  <xacro:macro name="ros2_HAA_joint" params="prefix">
    <joint name="${prefix}_HAA">
      <command_interface name="effort">
        <param name="min">-35</param>
        <param name="max">35</param>
      </command_interface>
      <state_interface name="position"/>
      <state_interface name="velocity"/>
      <state_interface name="effort"/>
    </joint>
  </xacro:macro>

  <xacro:macro name="ros2_HFE_joint" params="prefix">
    <joint name="${prefix}_HFE">
      <command_interface name="effort">
        <param name="min">-35</param>
        <param name="max">35</param>
      </command_interface>
      <state_interface name="position"/>
      <state_interface name="velocity"/>
      <state_interface name="effort"/>
    </joint>
  </xacro:macro>

  <xacro:macro name="ros2_KFE_joint" params="prefix">
    <joint name="${prefix}_KFE">
      <command_interface name="effort">
        <param name="min">-35</param>
        <param name="max">35</param>
      </command_interface>
      <state_interface name="position"/>
      <state_interface name="velocity"/>
      <state_interface name="effort"/>
    </joint>
  </xacro:macro>

  <xacro:macro name="orthrus_ros2_control" params="prefix name">

    <ros2_control name="${name}" type="system">
      <xacro:if value="${prefix == 'gazebo'}">
        <hardware>
          <plugin>gazebo_ros2_control/GazeboSystem</plugin>
        </hardware>
      </xacro:if>
      <xacro:if value="${prefix == 'real'}">
        <hardware>
          <plugin>orthrus_control/OrthrusSystemHardware</plugin>
        </hardware>
      </xacro:if>

      <xacro:ros2_HAA_joint prefix="RF"/>
      <xacro:ros2_HFE_joint prefix="RF"/>
      <xacro:ros2_KFE_joint prefix="RF"/>

      <xacro:ros2_HAA_joint prefix="LF"/>
      <xacro:ros2_HFE_joint prefix="LF"/>
      <xacro:ros2_KFE_joint prefix="LF"/>

      <xacro:ros2_HAA_joint prefix="RH"/>
      <xacro:ros2_HFE_joint prefix="RH"/>
      <xacro:ros2_KFE_joint prefix="RH"/>

      <xacro:ros2_HAA_joint prefix="LH"/>
      <xacro:ros2_HFE_joint prefix="LH"/>
      <xacro:ros2_KFE_joint prefix="LH"/>

      <sensor name="imu_sensor">
        <state_interface name="orientation.x"/>
        <state_interface name="orientation.y"/>
        <state_interface name="orientation.z"/>
        <state_interface name="orientation.w"/>
        <state_interface name="angular_velocity.x"/>
        <state_interface name="angular_velocity.y"/>
        <state_interface name="angular_velocity.z"/>
        <state_interface name="linear_acceleration.x"/>
        <state_interface name="linear_acceleration.y"/>
        <state_interface name="linear_acceleration.z"/>
      </sensor>

      <xacro:if value="${prefix == 'real'}">
        <sensor name="imu_lf">
          <state_interface name="orientation.x"/>
          <state_interface name="orientation.y"/>
          <state_interface name="orientation.z"/>
          <state_interface name="orientation.w"/>
        </sensor>
        <sensor name="imu_lh">
          <state_interface name="orientation.x"/>
          <state_interface name="orientation.y"/>
          <state_interface name="orientation.z"/>
          <state_interface name="orientation.w"/>
        </sensor>
        <sensor name="imu_rf">
          <state_interface name="orientation.x"/>
          <state_interface name="orientation.y"/>
          <state_interface name="orientation.z"/>
          <state_interface name="orientation.w"/>
        </sensor>
        <sensor name="imu_rh">
          <state_interface name="orientation.x"/>
          <state_interface name="orientation.y"/>
          <state_interface name="orientation.z"/>
          <state_interface name="orientation.w"/>
        </sensor>
      </xacro:if>

      <xacro:if value="${prefix == 'real'}">
        <gpio name="flag">
          <command_interface name="enable_power"/>
          <command_interface name="calibration_position"/>
          <command_interface name="calibration_encoder"/>
          <!-- Needed to know current state of the output -->
        </gpio>
      </xacro:if>

    </ros2_control>
  </xacro:macro>

</robot>


