<?xml version="1.0" ?>
<!-- =================================================================================== -->
<!-- |    This document was autogenerated by xacro from orthrus.urdf.xacro             | -->
<!-- |    EDITING THIS FILE BY HAND IS NOT RECOMMENDED                                 | -->
<!-- =================================================================================== -->
<robot name="orthrus">
  <material name="blue">
    <color rgba="0 0 0.8 1"/>
  </material>
  <material name="black">
    <color rgba="0 0 0 1"/>
  </material>
  <material name="white">
    <color rgba="1 1 1 1"/>
  </material>
  <link name="base">
    <visual>
      <origin rpy="1.5707963267948966 0 0" xyz="-0.10 0.1385 -0.05"/>
      <geometry>
        <mesh filename="file:////home/evence/code_file/ros2_ws/orthrus/install/orthrus_gazebo/share/orthrus_gazebo/models/orthrus/meshes/body.STL"/>
      </geometry>
      <material name="blue"/>
    </visual>
    <collision>
      <origin rpy="1.5707963267948966 0 0" xyz="-0.10 0.1385 -0.05"/>
      <geometry>
        <mesh filename="file:////home/evence/code_file/ros2_ws/orthrus/install/orthrus_gazebo/share/orthrus_gazebo/models/orthrus/meshes/body.STL"/>
      </geometry>
    </collision>
    <inertial>
      <mass value="7"/>
      <inertia ixx="4.9950395" ixy="0" ixz="0" iyy="2.4616377" iyz="0" izz="6.4183150"/>
    </inertial>
  </link>
  <link name="RF_HAA">
    <visual>
      <origin rpy="0 0 0" xyz="-0.02 -0.05 -0.05"/>
      <geometry>
        <mesh filename="file:////home/evence/code_file/ros2_ws/orthrus/install/orthrus_gazebo/share/orthrus_gazebo/models/orthrus/meshes/hip.STL"/>
      </geometry>
      <material name="black"/>
    </visual>
    <collision>
      <origin rpy="0 0 0" xyz="-0.02 -0.05 -0.05"/>
      <geometry>
        <mesh filename="file:////home/evence/code_file/ros2_ws/orthrus/install/orthrus_gazebo/share/orthrus_gazebo/models/orthrus/meshes/hip.STL"/>
      </geometry>
    </collision>
    <inertial>
      <mass value="0.7"/>
      <inertia ixx="0.0904981" ixy="0" ixz="-0.0000480" iyy=" 0.0917319" iyz="0" izz="0.0857923"/>
    </inertial>
  </link>
  <joint name="RF_HAA" type="revolute">
    <axis xyz="0 0 1"/>
    <parent link="base"/>
    <child link="RF_HAA"/>
    <dynamics damping="0.4" friction="0.3"/>
    <limit effort="35.0" lower="-1.5707963267948966" upper="1.5707963267948966" velocity="3.141592653589793"/>
    <origin rpy="-1.5707963267948966 3.141592653589793 3.141592653589793" xyz="0.05 0.20 0"/>
  </joint>
  <link name="LF_HAA">
    <visual>
      <origin rpy="0 0 0" xyz="-0.02 -0.05 -0.05"/>
      <geometry>
        <mesh filename="file:////home/evence/code_file/ros2_ws/orthrus/install/orthrus_gazebo/share/orthrus_gazebo/models/orthrus/meshes/hip.STL"/>
      </geometry>
      <material name="black"/>
    </visual>
    <collision>
      <origin rpy="0 0 0" xyz="-0.02 -0.05 -0.05"/>
      <geometry>
        <mesh filename="file:////home/evence/code_file/ros2_ws/orthrus/install/orthrus_gazebo/share/orthrus_gazebo/models/orthrus/meshes/hip.STL"/>
      </geometry>
    </collision>
    <inertial>
      <mass value="0.7"/>
      <inertia ixx="0.0904981" ixy="0" ixz="-0.0000480" iyy=" 0.0917319" iyz="0" izz="0.0857923"/>
    </inertial>
  </link>
  <joint name="LF_HAA" type="revolute">
    <axis xyz="0 0 1"/>
    <parent link="base"/>
    <child link="LF_HAA"/>
    <dynamics damping="0.4" friction="0.3"/>
    <limit effort="35.0" lower="-1.5707963267948966" upper="1.5707963267948966" velocity="3.141592653589793"/>
    <origin rpy="1.5707963267948966 3.141592653589793 0" xyz="-0.05 0.20 0"/>
  </joint>
  <link name="RH_HAA">
    <visual>
      <origin rpy="0 0 0" xyz="-0.02 -0.05 -0.05"/>
      <geometry>
        <mesh filename="file:////home/evence/code_file/ros2_ws/orthrus/install/orthrus_gazebo/share/orthrus_gazebo/models/orthrus/meshes/hip.STL"/>
      </geometry>
      <material name="black"/>
    </visual>
    <collision>
      <origin rpy="0 0 0" xyz="-0.02 -0.05 -0.05"/>
      <geometry>
        <mesh filename="file:////home/evence/code_file/ros2_ws/orthrus/install/orthrus_gazebo/share/orthrus_gazebo/models/orthrus/meshes/hip.STL"/>
      </geometry>
    </collision>
    <inertial>
      <mass value="0.7"/>
      <inertia ixx="0.0904981" ixy="0" ixz="-0.0000480" iyy=" 0.0917319" iyz="0" izz="0.0857923"/>
    </inertial>
  </link>
  <joint name="RH_HAA" type="revolute">
    <axis xyz="0 0 1"/>
    <parent link="base"/>
    <child link="RH_HAA"/>
    <dynamics damping="0.4" friction="0.3"/>
    <limit effort="35.0" lower="-1.5707963267948966" upper="1.5707963267948966" velocity="3.141592653589793"/>
    <origin rpy="1.5707963267948966 3.141592653589793 3.141592653589793" xyz="0.05 -0.20 0"/>
  </joint>
  <link name="LH_HAA">
    <visual>
      <origin rpy="0 0 0" xyz="-0.02 -0.05 -0.05"/>
      <geometry>
        <mesh filename="file:////home/evence/code_file/ros2_ws/orthrus/install/orthrus_gazebo/share/orthrus_gazebo/models/orthrus/meshes/hip.STL"/>
      </geometry>
      <material name="black"/>
    </visual>
    <collision>
      <origin rpy="0 0 0" xyz="-0.02 -0.05 -0.05"/>
      <geometry>
        <mesh filename="file:////home/evence/code_file/ros2_ws/orthrus/install/orthrus_gazebo/share/orthrus_gazebo/models/orthrus/meshes/hip.STL"/>
      </geometry>
    </collision>
    <inertial>
      <mass value="0.7"/>
      <inertia ixx="0.0904981" ixy="0" ixz="-0.0000480" iyy=" 0.0917319" iyz="0" izz="0.0857923"/>
    </inertial>
  </link>
  <joint name="LH_HAA" type="revolute">
    <axis xyz="0 0 1"/>
    <parent link="base"/>
    <child link="LH_HAA"/>
    <dynamics damping="0.4" friction="0.3"/>
    <limit effort="35.0" lower="-1.5707963267948966" upper="1.5707963267948966" velocity="3.141592653589793"/>
    <origin rpy="-1.5707963267948966 3.141592653589793 0" xyz="-0.05 -0.20 0"/>
  </joint>
  <link name="RF_HFE">
    <visual>
      <origin rpy="0 0 0" xyz="0 -0.2 -0.05"/>
      <geometry>
        <mesh filename="file:////home/evence/code_file/ros2_ws/orthrus/install/orthrus_gazebo/share/orthrus_gazebo/models/orthrus/meshes/leg1.STL"/>
      </geometry>
      <material name="black"/>
    </visual>
    <collision>
      <origin rpy="0 0 0" xyz="0 -0.2 -0.05"/>
      <geometry>
        <mesh filename="file:////home/evence/code_file/ros2_ws/orthrus/install/orthrus_gazebo/share/orthrus_gazebo/models/orthrus/meshes/leg1.STL"/>
      </geometry>
    </collision>
    <inertial>
      <mass value="1"/>
      <inertia ixx="0.4329464" ixy="-0.0830239" ixz=" -0.0000001" iyy="0.1503071" iyz="0.0000001" izz="0.4817994"/>
    </inertial>
  </link>
  <joint name="RF_HFE" type="revolute">
    <axis xyz="1 0 0"/>
    <parent link="RF_HAA"/>
    <child link="RF_HFE"/>
    <dynamics damping="0.4" friction="0.3"/>
    <limit effort="35.0" lower="-2.0943951023931953" upper="2.0943951023931953" velocity="3.141592653589793"/>
    <origin rpy="-1.5707963267948966 0 0" xyz="0.05 0 0"/>
  </joint>
  <link name="LF_HFE">
    <visual>
      <origin rpy="0 0 0" xyz="0 -0.2 -0.05"/>
      <geometry>
        <mesh filename="file:////home/evence/code_file/ros2_ws/orthrus/install/orthrus_gazebo/share/orthrus_gazebo/models/orthrus/meshes/leg1.STL"/>
      </geometry>
      <material name="black"/>
    </visual>
    <collision>
      <origin rpy="0 0 0" xyz="0 -0.2 -0.05"/>
      <geometry>
        <mesh filename="file:////home/evence/code_file/ros2_ws/orthrus/install/orthrus_gazebo/share/orthrus_gazebo/models/orthrus/meshes/leg1.STL"/>
      </geometry>
    </collision>
    <inertial>
      <mass value="1"/>
      <inertia ixx="0.4329464" ixy="-0.0830239" ixz=" -0.0000001" iyy="0.1503071" iyz="0.0000001" izz="0.4817994"/>
    </inertial>
  </link>
  <joint name="LF_HFE" type="revolute">
    <axis xyz="1 0 0"/>
    <parent link="LF_HAA"/>
    <child link="LF_HFE"/>
    <dynamics damping="0.4" friction="0.3"/>
    <limit effort="35.0" lower="-2.0943951023931953" upper="2.0943951023931953" velocity="3.141592653589793"/>
    <origin rpy="-1.5707963267948966 0 0" xyz="0.05 0 0"/>
  </joint>
  <link name="RH_HFE">
    <visual>
      <origin rpy="0 0 0" xyz="0 -0.2 -0.05"/>
      <geometry>
        <mesh filename="file:////home/evence/code_file/ros2_ws/orthrus/install/orthrus_gazebo/share/orthrus_gazebo/models/orthrus/meshes/leg1.STL"/>
      </geometry>
      <material name="black"/>
    </visual>
    <collision>
      <origin rpy="0 0 0" xyz="0 -0.2 -0.05"/>
      <geometry>
        <mesh filename="file:////home/evence/code_file/ros2_ws/orthrus/install/orthrus_gazebo/share/orthrus_gazebo/models/orthrus/meshes/leg1.STL"/>
      </geometry>
    </collision>
    <inertial>
      <mass value="1"/>
      <inertia ixx="0.4329464" ixy="-0.0830239" ixz=" -0.0000001" iyy="0.1503071" iyz="0.0000001" izz="0.4817994"/>
    </inertial>
  </link>
  <joint name="RH_HFE" type="revolute">
    <axis xyz="1 0 0"/>
    <parent link="RH_HAA"/>
    <child link="RH_HFE"/>
    <dynamics damping="0.4" friction="0.3"/>
    <limit effort="35.0" lower="-2.0943951023931953" upper="2.0943951023931953" velocity="3.141592653589793"/>
    <origin rpy="1.5707963267948966 0 0" xyz="0.05 0 0"/>
  </joint>
  <link name="LH_HFE">
    <visual>
      <origin rpy="0 0 0" xyz="0 -0.2 -0.05"/>
      <geometry>
        <mesh filename="file:////home/evence/code_file/ros2_ws/orthrus/install/orthrus_gazebo/share/orthrus_gazebo/models/orthrus/meshes/leg1.STL"/>
      </geometry>
      <material name="black"/>
    </visual>
    <collision>
      <origin rpy="0 0 0" xyz="0 -0.2 -0.05"/>
      <geometry>
        <mesh filename="file:////home/evence/code_file/ros2_ws/orthrus/install/orthrus_gazebo/share/orthrus_gazebo/models/orthrus/meshes/leg1.STL"/>
      </geometry>
    </collision>
    <inertial>
      <mass value="1"/>
      <inertia ixx="0.4329464" ixy="-0.0830239" ixz=" -0.0000001" iyy="0.1503071" iyz="0.0000001" izz="0.4817994"/>
    </inertial>
  </link>
  <joint name="LH_HFE" type="revolute">
    <axis xyz="1 0 0"/>
    <parent link="LH_HAA"/>
    <child link="LH_HFE"/>
    <dynamics damping="0.4" friction="0.3"/>
    <limit effort="35.0" lower="-2.0943951023931953" upper="2.0943951023931953" velocity="3.141592653589793"/>
    <origin rpy="1.5707963267948966 0 0" xyz="0.05 0 0"/>
  </joint>
  <link name="LF_KFE">
    <visual>
      <origin rpy="0 0 0" xyz="-0.025 -0.025 -0.225"/>
      <geometry>
        <mesh filename="file:////home/evence/code_file/ros2_ws/orthrus/install/orthrus_gazebo/share/orthrus_gazebo/models/orthrus/meshes/leg2.STL"/>
      </geometry>
      <material name="black"/>
    </visual>
    <collision>
      <origin rpy="0 0 0" xyz="-0.025 -0.025 -0.225"/>
      <geometry>
        <mesh filename="file:////home/evence/code_file/ros2_ws/orthrus/install/orthrus_gazebo/share/orthrus_gazebo/models/orthrus/meshes/leg2.STL"/>
      </geometry>
    </collision>
    <inertial>
      <mass value="0.2"/>
      <inertia ixx="0.4201680" ixy="0" ixz="0" iyy="0.4196489" iyz="0" izz="0.0031965"/>
    </inertial>
  </link>
  <joint name="LF_KFE" type="revolute">
    <axis xyz="1 0 0"/>
    <parent link="LF_HFE"/>
    <child link="LF_KFE"/>
    <dynamics damping="0.4" friction="0.3"/>
    <origin rpy="2.0943951023931953 0 0" xyz="0.035 -0.18 0"/>
    <limit effort="35.0" lower="-0.2617993877991494" upper="2.0943951023931953" velocity="3.141592653589793"/>
  </joint>
  <link name="RF_KFE">
    <visual>
      <origin rpy="0 0 0" xyz="-0.025 -0.025 -0.225"/>
      <geometry>
        <mesh filename="file:////home/evence/code_file/ros2_ws/orthrus/install/orthrus_gazebo/share/orthrus_gazebo/models/orthrus/meshes/leg2.STL"/>
      </geometry>
      <material name="black"/>
    </visual>
    <collision>
      <origin rpy="0 0 0" xyz="-0.025 -0.025 -0.225"/>
      <geometry>
        <mesh filename="file:////home/evence/code_file/ros2_ws/orthrus/install/orthrus_gazebo/share/orthrus_gazebo/models/orthrus/meshes/leg2.STL"/>
      </geometry>
    </collision>
    <inertial>
      <mass value="0.2"/>
      <inertia ixx="0.4201680" ixy="0" ixz="0" iyy="0.4196489" iyz="0" izz="0.0031965"/>
    </inertial>
  </link>
  <joint name="RF_KFE" type="revolute">
    <axis xyz="1 0 0"/>
    <parent link="RF_HFE"/>
    <child link="RF_KFE"/>
    <dynamics damping="0.4" friction="0.3"/>
    <origin rpy="1.0471975511965976 0 0" xyz="0.035 -0.18 0"/>
    <limit effort="35.0" lower="-2.0943951023931953" upper="0.2617993877991494" velocity="3.141592653589793"/>
  </joint>
  <link name="LH_KFE">
    <visual>
      <origin rpy="0 0 0" xyz="-0.025 -0.025 -0.225"/>
      <geometry>
        <mesh filename="file:////home/evence/code_file/ros2_ws/orthrus/install/orthrus_gazebo/share/orthrus_gazebo/models/orthrus/meshes/leg2.STL"/>
      </geometry>
      <material name="black"/>
    </visual>
    <collision>
      <origin rpy="0 0 0" xyz="-0.025 -0.025 -0.225"/>
      <geometry>
        <mesh filename="file:////home/evence/code_file/ros2_ws/orthrus/install/orthrus_gazebo/share/orthrus_gazebo/models/orthrus/meshes/leg2.STL"/>
      </geometry>
    </collision>
    <inertial>
      <mass value="0.2"/>
      <inertia ixx="0.4201680" ixy="0" ixz="0" iyy="0.4196489" iyz="0" izz="0.0031965"/>
    </inertial>
  </link>
  <joint name="LH_KFE" type="revolute">
    <axis xyz="1 0 0"/>
    <parent link="LH_HFE"/>
    <child link="LH_KFE"/>
    <dynamics damping="0.4" friction="0.3"/>
    <origin rpy="2.0943951023931953 0 0" xyz="0.035 -0.18 0"/>
    <limit effort="35.0" lower="-0.2617993877991494" upper="2.0943951023931953" velocity="3.141592653589793"/>
  </joint>
  <link name="RH_KFE">
    <visual>
      <origin rpy="0 0 0" xyz="-0.025 -0.025 -0.225"/>
      <geometry>
        <mesh filename="file:////home/evence/code_file/ros2_ws/orthrus/install/orthrus_gazebo/share/orthrus_gazebo/models/orthrus/meshes/leg2.STL"/>
      </geometry>
      <material name="black"/>
    </visual>
    <collision>
      <origin rpy="0 0 0" xyz="-0.025 -0.025 -0.225"/>
      <geometry>
        <mesh filename="file:////home/evence/code_file/ros2_ws/orthrus/install/orthrus_gazebo/share/orthrus_gazebo/models/orthrus/meshes/leg2.STL"/>
      </geometry>
    </collision>
    <inertial>
      <mass value="0.2"/>
      <inertia ixx="0.4201680" ixy="0" ixz="0" iyy="0.4196489" iyz="0" izz="0.0031965"/>
    </inertial>
  </link>
  <joint name="RH_KFE" type="revolute">
    <axis xyz="1 0 0"/>
    <parent link="RH_HFE"/>
    <child link="RH_KFE"/>
    <dynamics damping="0.4" friction="0.3"/>
    <origin rpy="1.0471975511965976 0 0" xyz="0.035 -0.18 0"/>
    <limit effort="35.0" lower="-2.0943951023931953" upper="0.2617993877991494" velocity="3.141592653589793"/>
  </joint>
  <gazebo reference="base">
    <sensor name="imu_sensor" type="imu">
      <always_on>1</always_on>
      <update_rate>1000</update_rate>
    </sensor>
  </gazebo>
  <ros2_control name="GazeboSystem" type="system">
    <hardware>
      <plugin>gazebo_ros2_control/GazeboSystem</plugin>
    </hardware>
    <joint name="HAA_RF_joint">
      <command_interface name="effort">
        <param name="min">-35</param>
        <param name="max">35</param>
      </command_interface>
      <state_interface name="position"/>
      <state_interface name="velocity"/>
      <state_interface name="effort"/>
    </joint>
    <joint name="HFE_RF_joint">
      <command_interface name="effort">
        <param name="min">-35</param>
        <param name="max">35</param>
      </command_interface>
      <state_interface name="position"/>
      <state_interface name="velocity"/>
      <state_interface name="effort"/>
    </joint>
    <joint name="KFE_RF_joint">
      <command_interface name="effort">
        <param name="min">-35</param>
        <param name="max">35</param>
      </command_interface>
      <state_interface name="position"/>
      <state_interface name="velocity"/>
      <state_interface name="effort"/>
    </joint>
    <joint name="HAA_LF_joint">
      <command_interface name="effort">
        <param name="min">-35</param>
        <param name="max">35</param>
      </command_interface>
      <state_interface name="position"/>
      <state_interface name="velocity"/>
      <state_interface name="effort"/>
    </joint>
    <joint name="HFE_LF_joint">
      <command_interface name="effort">
        <param name="min">-35</param>
        <param name="max">35</param>
      </command_interface>
      <state_interface name="position"/>
      <state_interface name="velocity"/>
      <state_interface name="effort"/>
    </joint>
    <joint name="KFE_LF_joint">
      <command_interface name="effort">
        <param name="min">-35</param>
        <param name="max">35</param>
      </command_interface>
      <state_interface name="position"/>
      <state_interface name="velocity"/>
      <state_interface name="effort"/>
    </joint>
    <joint name="HAA_RH_joint">
      <command_interface name="effort">
        <param name="min">-35</param>
        <param name="max">35</param>
      </command_interface>
      <state_interface name="position"/>
      <state_interface name="velocity"/>
      <state_interface name="effort"/>
    </joint>
    <joint name="HFE_RH_joint">
      <command_interface name="effort">
        <param name="min">-35</param>
        <param name="max">35</param>
      </command_interface>
      <state_interface name="position"/>
      <state_interface name="velocity"/>
      <state_interface name="effort"/>
    </joint>
    <joint name="KFE_RH_joint">
      <command_interface name="effort">
        <param name="min">-35</param>
        <param name="max">35</param>
      </command_interface>
      <state_interface name="position"/>
      <state_interface name="velocity"/>
      <state_interface name="effort"/>
    </joint>
    <joint name="HAA_LH_joint">
      <command_interface name="effort">
        <param name="min">-35</param>
        <param name="max">35</param>
      </command_interface>
      <state_interface name="position"/>
      <state_interface name="velocity"/>
      <state_interface name="effort"/>
    </joint>
    <joint name="HFE_LH_joint">
      <command_interface name="effort">
        <param name="min">-35</param>
        <param name="max">35</param>
      </command_interface>
      <state_interface name="position"/>
      <state_interface name="velocity"/>
      <state_interface name="effort"/>
    </joint>
    <joint name="KFE_LH_joint">
      <command_interface name="effort">
        <param name="min">-35</param>
        <param name="max">35</param>
      </command_interface>
      <state_interface name="position"/>
      <state_interface name="velocity"/>
      <state_interface name="effort"/>
    </joint>
    <sensor name="imu_sensor">
      <state_interface name="orientation.x"/>
      <state_interface name="orientation.y"/>
      <state_interface name="orientation.z"/>
      <state_interface name="orientation.w"/>
      <state_interface name="angular_velocity.x"/>
      <state_interface name="angular_velocity.y"/>
      <state_interface name="angular_velocity.z"/>
      <state_interface name="linear_acceleration.x"/>
      <state_interface name="linear_acceleration.y"/>
      <state_interface name="linear_acceleration.z"/>
    </sensor>
  </ros2_control>
  <gazebo>
    <plugin filename="libgazebo_ros2_control.so" name="gazebo_ros2_control">
      <parameters>/home/evence/code_file/ros2_ws/orthrus/src/orthrus_ros2_pack/orthrus_sim/orthrus_gazebo/config/orthrus.yaml</parameters>
    </plugin>
  </gazebo>
</robot>
