<?xml version="1.0" ?>
<!-- =================================================================================== -->
<!-- |    This document was autogenerated by xacro from orthrus_real.urdf.xacro        | -->
<!-- |    EDITING THIS FILE BY HAND IS NOT RECOMMENDED                                 | -->
<!-- =================================================================================== -->
<robot name="orthrus">
  <material name="blue">
    <color rgba="0 0 0.8 1"/>
  </material>
  <material name="black">
    <color rgba="0 0 0 1"/>
  </material>
  <material name="white">
    <color rgba="1 1 1 1"/>
  </material>
  <link name="base">
    <visual>
      <origin rpy="1.5707963267948966 0 1.5707963267948966" xyz="-0.1385 -0.10 -0.05"/>
      <geometry>
        <mesh filename="file:////home/evence/code_file/ros2_ws/orthrus/install/orthrus_interfaces/share/orthrus_interfaces/models/orthrus/meshes/body.STL"/>
      </geometry>
      <material name="blue"/>
    </visual>
    <collision>
      <origin rpy="1.5707963267948966 0 1.5707963267948966" xyz="-0.1385 -0.10 -0.05"/>
      <geometry>
        <mesh filename="file:////home/evence/code_file/ros2_ws/orthrus/install/orthrus_interfaces/share/orthrus_interfaces/models/orthrus/meshes/body.STL"/>
      </geometry>
    </collision>
    <inertial>
      <origin rpy="0 0 0" xyz="-0.010977 0.000003 -0.000477"/>
      <mass value="4.429"/>
      <inertia ixx="0.014923275" ixy="-0.000034837" ixz=" -0.000020438" iyy="0.050690680" iyz="0.000209222" izz="0.057629196"/>
    </inertial>
  </link>
  <link name="LF_HAA_link">
    <visual>
      <origin rpy="0 0 0" xyz="-0.02 -0.05 -0.05"/>
      <geometry>
        <mesh filename="file:////home/evence/code_file/ros2_ws/orthrus/install/orthrus_interfaces/share/orthrus_interfaces/models/orthrus/meshes/hip.STL"/>
      </geometry>
      <material name="black"/>
    </visual>
    <collision>
      <origin rpy="0 0 0" xyz="-0.02 -0.05 -0.05"/>
      <geometry>
        <mesh filename="file:////home/evence/code_file/ros2_ws/orthrus/install/orthrus_interfaces/share/orthrus_interfaces/models/orthrus/meshes/hip.STL"/>
      </geometry>
    </collision>
    <inertial>
      <origin rpy="0 0 0" xyz="0.003391 0.000355 0.001734"/>
      <mass value="0.67"/>
      <inertia ixx="-0.000849931" ixy="-0.000005571" ixz="0.000007520" iyy="0.000608499" iyz="-0.000003845" izz="0.000546025"/>
    </inertial>
  </link>
  <joint name="LF_HAA" type="revolute">
    <axis xyz="0 0 1"/>
    <parent link="base"/>
    <child link="LF_HAA_link"/>
    <dynamics damping="0.4" friction="0.3"/>
    <limit effort="35.0" lower="-1.5707963267948966" upper="1.5707963267948966" velocity="3.141592653589793"/>
    <origin rpy="1.5707963267948966 3.141592653589793 -1.5707963267948966" xyz="0.20 0.05 0"/>
  </joint>
  <link name="LF_HFE_link">
    <visual>
      <origin rpy="0 0 0" xyz="0 -0.2 -0.05"/>
      <geometry>
        <mesh filename="file:////home/evence/code_file/ros2_ws/orthrus/install/orthrus_interfaces/share/orthrus_interfaces/models/orthrus/meshes/leg1.STL"/>
      </geometry>
      <material name="black"/>
    </visual>
    <collision>
      <origin rpy="0 0 0" xyz="0 -0.2 -0.05"/>
      <geometry>
        <mesh filename="file:////home/evence/code_file/ros2_ws/orthrus/install/orthrus_interfaces/share/orthrus_interfaces/models/orthrus/meshes/leg1.STL"/>
      </geometry>
    </collision>
    <inertial>
      <origin rpy="0 0 0" xyz="0.013465 -0.021755 -0.000094"/>
      <mass value="0.928"/>
      <inertia ixx="0.003597820" ixy="-0.000526099" ixz="-0.000000377" iyy="0.001042179" iyz="0.000060684" izz="0.003628939"/>
    </inertial>
  </link>
  <joint name="LF_HFE" type="revolute">
    <axis xyz="1 0 0"/>
    <parent link="LF_HAA_link"/>
    <child link="LF_HFE_link"/>
    <dynamics damping="0.4" friction="0.3"/>
    <limit effort="35.0" lower="-2.0943951023931953" upper="2.0943951023931953" velocity="3.141592653589793"/>
    <origin rpy="-1.5707963267948966 0 0" xyz="0.05 0 0"/>
  </joint>
  <link name="LF_KFE_link">
    <visual>
      <origin rpy="0 0 0" xyz="-0.025 -0.025 -0.225"/>
      <geometry>
        <mesh filename="file:////home/evence/code_file/ros2_ws/orthrus/install/orthrus_interfaces/share/orthrus_interfaces/models/orthrus/meshes/leg2.STL"/>
      </geometry>
      <material name="black"/>
    </visual>
    <collision>
      <origin rpy="0 0 0" xyz="-0.025 -0.025 -0.225"/>
      <geometry>
        <mesh filename="file:////home/evence/code_file/ros2_ws/orthrus/install/orthrus_interfaces/share/orthrus_interfaces/models/orthrus/meshes/leg2.STL"/>
      </geometry>
    </collision>
    <inertial>
      <origin rpy="0 0 0" xyz="-0.000162 -0.000597 -0.068453"/>
      <mass value="0.187"/>
      <inertia ixx="0.001261336" ixy="0.000000011" ixz="-0.000001541" iyy="0.001259961" iyz="-0.0000059890" izz="0.000033267"/>
    </inertial>
  </link>
  <joint name="LF_KFE" type="revolute">
    <axis xyz="1 0 0"/>
    <parent link="LF_HFE_link"/>
    <child link="LF_KFE_link"/>
    <dynamics damping="0.4" friction="0.3"/>
    <origin rpy="2.0943951023931953 0 0" xyz="0.035 -0.18 0"/>
    <limit effort="35.0" lower="-0.2617993877991494" upper="2.0943951023931953" velocity="3.141592653589793"/>
  </joint>
  <link name="LF_FOOT_link">
    </link>
  <joint name="LF_FOOT" type="fixed">
    <axis xyz="1 0 0"/>
    <parent link="LF_KFE_link"/>
    <child link="LF_FOOT_link"/>
    <origin rpy="0 0 0" xyz="0.0 0.0 -0.2"/>
  </joint>
  <link name="LH_HAA_link">
    <visual>
      <origin rpy="0 0 0" xyz="-0.02 -0.05 -0.05"/>
      <geometry>
        <mesh filename="file:////home/evence/code_file/ros2_ws/orthrus/install/orthrus_interfaces/share/orthrus_interfaces/models/orthrus/meshes/hip.STL"/>
      </geometry>
      <material name="black"/>
    </visual>
    <collision>
      <origin rpy="0 0 0" xyz="-0.02 -0.05 -0.05"/>
      <geometry>
        <mesh filename="file:////home/evence/code_file/ros2_ws/orthrus/install/orthrus_interfaces/share/orthrus_interfaces/models/orthrus/meshes/hip.STL"/>
      </geometry>
    </collision>
    <inertial>
      <origin rpy="0 0 0" xyz="0.003391 0.000355 0.001734"/>
      <mass value="0.67"/>
      <inertia ixx="-0.000849931" ixy="-0.000005571" ixz="0.000007520" iyy="0.000608499" iyz="-0.000003845" izz="0.000546025"/>
    </inertial>
  </link>
  <joint name="LH_HAA" type="revolute">
    <axis xyz="0 0 1"/>
    <parent link="base"/>
    <child link="LH_HAA_link"/>
    <dynamics damping="0.4" friction="0.3"/>
    <limit effort="35.0" lower="-1.5707963267948966" upper="1.5707963267948966" velocity="3.141592653589793"/>
    <origin rpy="-1.5707963267948966 3.141592653589793 -1.5707963267948966" xyz="-0.20 0.05 0"/>
  </joint>
  <link name="LH_HFE_link">
    <visual>
      <origin rpy="0 0 0" xyz="0 -0.2 -0.05"/>
      <geometry>
        <mesh filename="file:////home/evence/code_file/ros2_ws/orthrus/install/orthrus_interfaces/share/orthrus_interfaces/models/orthrus/meshes/leg1.STL"/>
      </geometry>
      <material name="black"/>
    </visual>
    <collision>
      <origin rpy="0 0 0" xyz="0 -0.2 -0.05"/>
      <geometry>
        <mesh filename="file:////home/evence/code_file/ros2_ws/orthrus/install/orthrus_interfaces/share/orthrus_interfaces/models/orthrus/meshes/leg1.STL"/>
      </geometry>
    </collision>
    <inertial>
      <origin rpy="0 0 0" xyz="0.013465 -0.021755 -0.000094"/>
      <mass value="0.928"/>
      <inertia ixx="0.003597820" ixy="-0.000526099" ixz="-0.000000377" iyy="0.001042179" iyz="0.000060684" izz="0.003628939"/>
    </inertial>
  </link>
  <joint name="LH_HFE" type="revolute">
    <axis xyz="1 0 0"/>
    <parent link="LH_HAA_link"/>
    <child link="LH_HFE_link"/>
    <dynamics damping="0.4" friction="0.3"/>
    <limit effort="35.0" lower="-2.0943951023931953" upper="2.0943951023931953" velocity="3.141592653589793"/>
    <origin rpy="1.5707963267948966 0 0" xyz="0.05 0 0"/>
  </joint>
  <link name="LH_KFE_link">
    <visual>
      <origin rpy="0 0 0" xyz="-0.025 -0.025 -0.225"/>
      <geometry>
        <mesh filename="file:////home/evence/code_file/ros2_ws/orthrus/install/orthrus_interfaces/share/orthrus_interfaces/models/orthrus/meshes/leg2.STL"/>
      </geometry>
      <material name="black"/>
    </visual>
    <collision>
      <origin rpy="0 0 0" xyz="-0.025 -0.025 -0.225"/>
      <geometry>
        <mesh filename="file:////home/evence/code_file/ros2_ws/orthrus/install/orthrus_interfaces/share/orthrus_interfaces/models/orthrus/meshes/leg2.STL"/>
      </geometry>
    </collision>
    <inertial>
      <origin rpy="0 0 0" xyz="-0.000162 -0.000597 -0.068453"/>
      <mass value="0.187"/>
      <inertia ixx="0.001261336" ixy="0.000000011" ixz="-0.000001541" iyy="0.001259961" iyz="-0.0000059890" izz="0.000033267"/>
    </inertial>
  </link>
  <joint name="LH_KFE" type="revolute">
    <axis xyz="1 0 0"/>
    <parent link="LH_HFE_link"/>
    <child link="LH_KFE_link"/>
    <dynamics damping="0.4" friction="0.3"/>
    <origin rpy="2.0943951023931953 0 0" xyz="0.035 -0.18 0"/>
    <limit effort="35.0" lower="-0.2617993877991494" upper="2.0943951023931953" velocity="3.141592653589793"/>
  </joint>
  <link name="LH_FOOT_link">
    </link>
  <joint name="LH_FOOT" type="fixed">
    <axis xyz="1 0 0"/>
    <parent link="LH_KFE_link"/>
    <child link="LH_FOOT_link"/>
    <origin rpy="0 0 0" xyz="0.0 0.0 -0.2"/>
  </joint>
  <link name="RF_HAA_link">
    <visual>
      <origin rpy="0 0 0" xyz="-0.02 -0.05 -0.05"/>
      <geometry>
        <mesh filename="file:////home/evence/code_file/ros2_ws/orthrus/install/orthrus_interfaces/share/orthrus_interfaces/models/orthrus/meshes/hip.STL"/>
      </geometry>
      <material name="black"/>
    </visual>
    <collision>
      <origin rpy="0 0 0" xyz="-0.02 -0.05 -0.05"/>
      <geometry>
        <mesh filename="file:////home/evence/code_file/ros2_ws/orthrus/install/orthrus_interfaces/share/orthrus_interfaces/models/orthrus/meshes/hip.STL"/>
      </geometry>
    </collision>
    <inertial>
      <origin rpy="0 0 0" xyz="0.003391 0.000355 0.001734"/>
      <mass value="0.67"/>
      <inertia ixx="-0.000849931" ixy="-0.000005571" ixz="0.000007520" iyy="0.000608499" iyz="-0.000003845" izz="0.000546025"/>
    </inertial>
  </link>
  <joint name="RF_HAA" type="revolute">
    <axis xyz="0 0 1"/>
    <parent link="base"/>
    <child link="RF_HAA_link"/>
    <dynamics damping="0.4" friction="0.3"/>
    <limit effort="35.0" lower="-1.5707963267948966" upper="1.5707963267948966" velocity="3.141592653589793"/>
    <origin rpy="-1.5707963267948966 3.141592653589793 1.5707963267948966" xyz="0.20 -0.05 0"/>
  </joint>
  <link name="RF_HFE_link">
    <visual>
      <origin rpy="0 0 0" xyz="0 -0.2 -0.05"/>
      <geometry>
        <mesh filename="file:////home/evence/code_file/ros2_ws/orthrus/install/orthrus_interfaces/share/orthrus_interfaces/models/orthrus/meshes/leg1.STL"/>
      </geometry>
      <material name="black"/>
    </visual>
    <collision>
      <origin rpy="0 0 0" xyz="0 -0.2 -0.05"/>
      <geometry>
        <mesh filename="file:////home/evence/code_file/ros2_ws/orthrus/install/orthrus_interfaces/share/orthrus_interfaces/models/orthrus/meshes/leg1.STL"/>
      </geometry>
    </collision>
    <inertial>
      <origin rpy="0 0 0" xyz="0.013465 -0.021755 0.000094"/>
      <mass value="0.928"/>
      <inertia ixx="0.003597820" ixy="-0.000526099" ixz="-0.000000377" iyy="0.001042179" iyz="0.000060684" izz="0.003628939"/>
    </inertial>
  </link>
  <joint name="RF_HFE" type="revolute">
    <axis xyz="1 0 0"/>
    <parent link="RF_HAA_link"/>
    <child link="RF_HFE_link"/>
    <dynamics damping="0.4" friction="0.3"/>
    <limit effort="35.0" lower="-2.0943951023931953" upper="2.0943951023931953" velocity="3.141592653589793"/>
    <origin rpy="-1.5707963267948966 0 0" xyz="0.05 0 0"/>
  </joint>
  <link name="RF_KFE_link">
    <visual>
      <origin rpy="0 0 0" xyz="-0.025 -0.025 -0.225"/>
      <geometry>
        <mesh filename="file:////home/evence/code_file/ros2_ws/orthrus/install/orthrus_interfaces/share/orthrus_interfaces/models/orthrus/meshes/leg2.STL"/>
      </geometry>
      <material name="black"/>
    </visual>
    <collision>
      <origin rpy="0 0 0" xyz="-0.025 -0.025 -0.225"/>
      <geometry>
        <mesh filename="file:////home/evence/code_file/ros2_ws/orthrus/install/orthrus_interfaces/share/orthrus_interfaces/models/orthrus/meshes/leg2.STL"/>
      </geometry>
    </collision>
    <inertial>
      <origin rpy="0 0 0" xyz="-0.000162 0.000597 -0.068453"/>
      <mass value="0.187"/>
      <inertia ixx="0.001261336" ixy="0.000000011" ixz="-0.000001541" iyy="0.001259961" iyz="-0.0000059890" izz="0.000033267"/>
    </inertial>
  </link>
  <joint name="RF_KFE" type="revolute">
    <axis xyz="1 0 0"/>
    <parent link="RF_HFE_link"/>
    <child link="RF_KFE_link"/>
    <dynamics damping="0.4" friction="0.3"/>
    <origin rpy="1.0471975511965976 0 0" xyz="0.035 -0.18 0"/>
    <limit effort="35.0" lower="-2.0943951023931953" upper="0.2617993877991494" velocity="3.141592653589793"/>
  </joint>
  <link name="RF_FOOT_link">
    </link>
  <joint name="RF_FOOT" type="fixed">
    <axis xyz="1 0 0"/>
    <parent link="RF_KFE_link"/>
    <child link="RF_FOOT_link"/>
    <origin rpy="0 0 0" xyz="0.0 0.0 -0.2"/>
  </joint>
  <link name="RH_HAA_link">
    <visual>
      <origin rpy="0 0 0" xyz="-0.02 -0.05 -0.05"/>
      <geometry>
        <mesh filename="file:////home/evence/code_file/ros2_ws/orthrus/install/orthrus_interfaces/share/orthrus_interfaces/models/orthrus/meshes/hip.STL"/>
      </geometry>
      <material name="black"/>
    </visual>
    <collision>
      <origin rpy="0 0 0" xyz="-0.02 -0.05 -0.05"/>
      <geometry>
        <mesh filename="file:////home/evence/code_file/ros2_ws/orthrus/install/orthrus_interfaces/share/orthrus_interfaces/models/orthrus/meshes/hip.STL"/>
      </geometry>
    </collision>
    <inertial>
      <origin rpy="0 0 0" xyz="0.003391 0.000355 0.001734"/>
      <mass value="0.67"/>
      <inertia ixx="-0.000849931" ixy="-0.000005571" ixz="0.000007520" iyy="0.000608499" iyz="-0.000003845" izz="0.000546025"/>
    </inertial>
  </link>
  <joint name="RH_HAA" type="revolute">
    <axis xyz="0 0 1"/>
    <parent link="base"/>
    <child link="RH_HAA_link"/>
    <dynamics damping="0.4" friction="0.3"/>
    <limit effort="35.0" lower="-1.5707963267948966" upper="1.5707963267948966" velocity="3.141592653589793"/>
    <origin rpy="1.5707963267948966 3.141592653589793 1.5707963267948966" xyz="-0.20 -0.05 0"/>
  </joint>
  <link name="RH_HFE_link">
    <visual>
      <origin rpy="0 0 0" xyz="0 -0.2 -0.05"/>
      <geometry>
        <mesh filename="file:////home/evence/code_file/ros2_ws/orthrus/install/orthrus_interfaces/share/orthrus_interfaces/models/orthrus/meshes/leg1.STL"/>
      </geometry>
      <material name="black"/>
    </visual>
    <collision>
      <origin rpy="0 0 0" xyz="0 -0.2 -0.05"/>
      <geometry>
        <mesh filename="file:////home/evence/code_file/ros2_ws/orthrus/install/orthrus_interfaces/share/orthrus_interfaces/models/orthrus/meshes/leg1.STL"/>
      </geometry>
    </collision>
    <inertial>
      <origin rpy="0 0 0" xyz="0.013465 -0.021755 0.000094"/>
      <mass value="0.928"/>
      <inertia ixx="0.003597820" ixy="-0.000526099" ixz="-0.000000377" iyy="0.001042179" iyz="0.000060684" izz="0.003628939"/>
    </inertial>
  </link>
  <joint name="RH_HFE" type="revolute">
    <axis xyz="1 0 0"/>
    <parent link="RH_HAA_link"/>
    <child link="RH_HFE_link"/>
    <dynamics damping="0.4" friction="0.3"/>
    <limit effort="35.0" lower="-2.0943951023931953" upper="2.0943951023931953" velocity="3.141592653589793"/>
    <origin rpy="1.5707963267948966 0 0" xyz="0.05 0 0"/>
  </joint>
  <link name="RH_KFE_link">
    <visual>
      <origin rpy="0 0 0" xyz="-0.025 -0.025 -0.225"/>
      <geometry>
        <mesh filename="file:////home/evence/code_file/ros2_ws/orthrus/install/orthrus_interfaces/share/orthrus_interfaces/models/orthrus/meshes/leg2.STL"/>
      </geometry>
      <material name="black"/>
    </visual>
    <collision>
      <origin rpy="0 0 0" xyz="-0.025 -0.025 -0.225"/>
      <geometry>
        <mesh filename="file:////home/evence/code_file/ros2_ws/orthrus/install/orthrus_interfaces/share/orthrus_interfaces/models/orthrus/meshes/leg2.STL"/>
      </geometry>
    </collision>
    <inertial>
      <origin rpy="0 0 0" xyz="-0.000162 0.000597 -0.068453"/>
      <mass value="0.187"/>
      <inertia ixx="0.001261336" ixy="0.000000011" ixz="-0.000001541" iyy="0.001259961" iyz="-0.0000059890" izz="0.000033267"/>
    </inertial>
  </link>
  <joint name="RH_KFE" type="revolute">
    <axis xyz="1 0 0"/>
    <parent link="RH_HFE_link"/>
    <child link="RH_KFE_link"/>
    <dynamics damping="0.4" friction="0.3"/>
    <origin rpy="1.0471975511965976 0 0" xyz="0.035 -0.18 0"/>
    <limit effort="35.0" lower="-2.0943951023931953" upper="0.2617993877991494" velocity="3.141592653589793"/>
  </joint>
  <link name="RH_FOOT_link">
    </link>
  <joint name="RH_FOOT" type="fixed">
    <axis xyz="1 0 0"/>
    <parent link="RH_KFE_link"/>
    <child link="RH_FOOT_link"/>
    <origin rpy="0 0 0" xyz="0.0 0.0 -0.2"/>
  </joint>
  <ros2_control name="OrthrusSystemHardware" type="system">
    <hardware>
      <plugin>orthrus_control/OrthrusSystemHardware</plugin>
    </hardware>
    <joint name="RF_HAA">
      <command_interface name="effort">
        <param name="min">-35</param>
        <param name="max">35</param>
      </command_interface>
      <state_interface name="position"/>
      <state_interface name="velocity"/>
      <state_interface name="effort"/>
    </joint>
    <joint name="RF_HFE">
      <command_interface name="effort">
        <param name="min">-35</param>
        <param name="max">35</param>
      </command_interface>
      <state_interface name="position"/>
      <state_interface name="velocity"/>
      <state_interface name="effort"/>
    </joint>
    <joint name="RF_KFE">
      <command_interface name="effort">
        <param name="min">-35</param>
        <param name="max">35</param>
      </command_interface>
      <state_interface name="position"/>
      <state_interface name="velocity"/>
      <state_interface name="effort"/>
    </joint>
    <joint name="LF_HAA">
      <command_interface name="effort">
        <param name="min">-35</param>
        <param name="max">35</param>
      </command_interface>
      <state_interface name="position"/>
      <state_interface name="velocity"/>
      <state_interface name="effort"/>
    </joint>
    <joint name="LF_HFE">
      <command_interface name="effort">
        <param name="min">-35</param>
        <param name="max">35</param>
      </command_interface>
      <state_interface name="position"/>
      <state_interface name="velocity"/>
      <state_interface name="effort"/>
    </joint>
    <joint name="LF_KFE">
      <command_interface name="effort">
        <param name="min">-35</param>
        <param name="max">35</param>
      </command_interface>
      <state_interface name="position"/>
      <state_interface name="velocity"/>
      <state_interface name="effort"/>
    </joint>
    <joint name="RH_HAA">
      <command_interface name="effort">
        <param name="min">-35</param>
        <param name="max">35</param>
      </command_interface>
      <state_interface name="position"/>
      <state_interface name="velocity"/>
      <state_interface name="effort"/>
    </joint>
    <joint name="RH_HFE">
      <command_interface name="effort">
        <param name="min">-35</param>
        <param name="max">35</param>
      </command_interface>
      <state_interface name="position"/>
      <state_interface name="velocity"/>
      <state_interface name="effort"/>
    </joint>
    <joint name="RH_KFE">
      <command_interface name="effort">
        <param name="min">-35</param>
        <param name="max">35</param>
      </command_interface>
      <state_interface name="position"/>
      <state_interface name="velocity"/>
      <state_interface name="effort"/>
    </joint>
    <joint name="LH_HAA">
      <command_interface name="effort">
        <param name="min">-35</param>
        <param name="max">35</param>
      </command_interface>
      <state_interface name="position"/>
      <state_interface name="velocity"/>
      <state_interface name="effort"/>
    </joint>
    <joint name="LH_HFE">
      <command_interface name="effort">
        <param name="min">-35</param>
        <param name="max">35</param>
      </command_interface>
      <state_interface name="position"/>
      <state_interface name="velocity"/>
      <state_interface name="effort"/>
    </joint>
    <joint name="LH_KFE">
      <command_interface name="effort">
        <param name="min">-35</param>
        <param name="max">35</param>
      </command_interface>
      <state_interface name="position"/>
      <state_interface name="velocity"/>
      <state_interface name="effort"/>
    </joint>
    <sensor name="imu_sensor">
      <state_interface name="orientation.x"/>
      <state_interface name="orientation.y"/>
      <state_interface name="orientation.z"/>
      <state_interface name="orientation.w"/>
      <state_interface name="angular_velocity.x"/>
      <state_interface name="angular_velocity.y"/>
      <state_interface name="angular_velocity.z"/>
      <state_interface name="linear_acceleration.x"/>
      <state_interface name="linear_acceleration.y"/>
      <state_interface name="linear_acceleration.z"/>
    </sensor>
    <sensor name="imu_lf">
      <state_interface name="orientation.x"/>
      <state_interface name="orientation.y"/>
      <state_interface name="orientation.z"/>
      <state_interface name="orientation.w"/>
    </sensor>
    <sensor name="imu_lh">
      <state_interface name="orientation.x"/>
      <state_interface name="orientation.y"/>
      <state_interface name="orientation.z"/>
      <state_interface name="orientation.w"/>
    </sensor>
    <sensor name="imu_rf">
      <state_interface name="orientation.x"/>
      <state_interface name="orientation.y"/>
      <state_interface name="orientation.z"/>
      <state_interface name="orientation.w"/>
    </sensor>
    <sensor name="imu_rh">
      <state_interface name="orientation.x"/>
      <state_interface name="orientation.y"/>
      <state_interface name="orientation.z"/>
      <state_interface name="orientation.w"/>
    </sensor>
    <gpio name="flag">
      <command_interface name="enable_power"/>
      <command_interface name="calibration_position"/>
      <command_interface name="calibration_encoder"/>
      <!-- Needed to know current state of the output -->
    </gpio>
  </ros2_control>
</robot>
